Workbook

Sheet Sheet1
A1: Fornavn | B1: Etternavn | C1: E-post | D1: Land | E1: Landskode | F1: Fødselsdato | G1: Alder | H1: Mobil | I1: Kjønn | J1: Klubb | K1: Klubb-ID | L1: Gruppe-ID | M1: Krets/region | N1: Krets/region ID | O1: Kommentar | P1: Sport | Q1: Øvelse | R1: Klasse | S1: Dato | T1: Kl. | U1: Sum | V1: Mva | W1: Lisens | X1: Helårslisens | Y1: Engangslisens | Z1: Påmeldt av | AA1: E-post påmelder | AB1: Påmelder betalte | AC1: Påmelder betalte mva | AD1: Betalt | AE1: Transaksjons-ID | AF1: Påmeldings-ID | AG1: Påmeldingsstatus | AH1: Påmeldt dato | AI1: Påmeldt kl. | AJ1: Deltakerstatus | AK1: Alle betalinger | AL1: Buypass ID | AM1: Person ID | AN1: Påmeldingsavgift | AO1: Påmeldingsavgift mva | AP1: Markedskommunikasjon | AQ1: Mediesamtykke
A2: Viljar Herman Porserud | B2: Norvik | C2: jonviljar@gmail.com | D2: Norge | E2: NOR | F2: 22.05.2016 | G2: 8 år | H2: +4795923292 | I2: M | J2: IL i BUL Tromsø | K2: 28037 | L2: 58354 | M2: Troms friidrettskrets | N2: 555 | P2: Friidrett på bane | Q2: 300 meter | R2: Gutter 10 | S2: 24.02.2025 | T2: 17:00 | U2: 0 | V2: 0 | W2: N | Z2: Jon Viljar Porserud Norvik | AA2: jonviljar@gmail.com | AB2: 0 | AC2: 0 | AD2: Ja | AF2: cm6q6lexy000l7001lror7oag | AG2: Påmeldt | AH2: 04.02.2025 | AI2: 08:52 | AJ2: Ikke sjekket inn | AK2: Betaling nr: 1 (PAID) Beløp: 0,- | AL2: 135590552 | AM2: 8275269 | AP2: Nei | AQ2: Ja
A3: Viljar Herman Porserud | B3: Norvik | C3: jonviljar@gmail.com | D3: Norge | E3: NOR | F3: 22.05.2016 | G3: 8 år | H3: +4795923292 | I3: M | J3: IL i BUL Tromsø | K3: 28037 | L3: 58354 | M3: Troms friidrettskrets | N3: 555 | P3: Friidrett på bane | Q3: Høyde | R3: Gutter 10 | S3: 24.02.2025 | T3: 17:00 | U3: 0 | V3: 0 | W3: N | Z3: Jon Viljar Porserud Norvik | AA3: jonviljar@gmail.com | AB3: 0 | AC3: 0 | AD3: Ja | AF3: cm6q6lexy000l7001lror7oag | AG3: Påmeldt | AH3: 04.02.2025 | AI3: 08:52 | AJ3: Ikke sjekket inn | AK3: Betaling nr: 1 (PAID) Beløp: 0,- | AL3: 135590552 | AM3: 8275269 | AP3: Nei | AQ3: Ja
A4: Viljar Herman Porserud | B4: Norvik | C4: jonviljar@gmail.com | D4: Norge | E4: NOR | F4: 22.05.2016 | G4: 8 år | H4: +4795923292 | I4: M | J4: IL i BUL Tromsø | K4: 28037 | L4: 58354 | M4: Troms friidrettskrets | N4: 555 | P4: Friidrett på bane | Q4: Kule | R4: Gutter 10 | S4: 24.02.2025 | T4: 17:00 | U4: 0 | V4: 0 | W4: N | Z4: Jon Viljar Porserud Norvik | AA4: jonviljar@gmail.com | AB4: 0 | AC4: 0 | AD4: Ja | AF4: cm6q6lexy000l7001lror7oag | AG4: Påmeldt | AH4: 04.02.2025 | AI4: 08:52 | AJ4: Ikke sjekket inn | AK4: Betaling nr: 1 (PAID) Beløp: 0,- | AL4: 135590552 | AM4: 8275269 | AP4: Nei | AQ4: Ja
A5: Samuel Helmer Porserud | B5: Norvik | C5: jonviljar@gmail.com | D5: Norge | E5: NOR | F5: 17.05.2018 | G5: 6 år | H5: +4795923292 | I5: M | J5: IL i BUL Tromsø | K5: 28037 | L5: 58354 | M5: Troms friidrettskrets | N5: 555 | P5: Friidrett på bane | Q5: 300 meter | R5: Gutter 10 | S5: 24.02.2025 | T5: 17:00 | U5: 0 | V5: 0 | W5: N | Z5: Jon Viljar Porserud Norvik | AA5: jonviljar@gmail.com | AB5: 0 | AC5: 0 | AD5: Ja | AF5: cm6q6lexy000l7001lror7oag | AG5: Påmeldt | AH5: 04.02.2025 | AI5: 08:52 | AJ5: Ikke sjekket inn | AK5: Betaling nr: 1 (PAID) Beløp: 0,- | AL5: 000000000 | AM5: 9826897 | AP5: Nei | AQ5: Ja
A6: Samuel Helmer Porserud | B6: Norvik | C6: jonviljar@gmail.com | D6: Norge | E6: NOR | F6: 17.05.2018 | G6: 6 år | H6: +4795923292 | I6: M | J6: IL i BUL Tromsø | K6: 28037 | L6: 58354 | M6: Troms friidrettskrets | N6: 555 | P6: Friidrett på bane | Q6: Høyde | R6: Gutter 10 | S6: 24.02.2025 | T6: 17:00 | U6: 0 | V6: 0 | W6: N | Z6: Jon Viljar Porserud Norvik | AA6: jonviljar@gmail.com | AB6: 0 | AC6: 0 | AD6: Ja | AF6: cm6q6lexy000l7001lror7oag | AG6: Påmeldt | AH6: 04.02.2025 | AI6: 08:52 | AJ6: Ikke sjekket inn | AK6: Betaling nr: 1 (PAID) Beløp: 0,- | AL6: 000000000 | AM6: 9826897 | AP6: Nei | AQ6: Ja
A7: Samuel Helmer Porserud | B7: Norvik | C7: jonviljar@gmail.com | D7: Norge | E7: NOR | F7: 17.05.2018 | G7: 6 år | H7: +4795923292 | I7: M | J7: IL i BUL Tromsø | K7: 28037 | L7: 58354 | M7: Troms friidrettskrets | N7: 555 | P7: Friidrett på bane | Q7: Kule | R7: Gutter 10 | S7: 24.02.2025 | T7: 17:00 | U7: 0 | V7: 0 | W7: N | Z7: Jon Viljar Porserud Norvik | AA7: jonviljar@gmail.com | AB7: 0 | AC7: 0 | AD7: Ja | AF7: cm6q6lexy000l7001lror7oag | AG7: Påmeldt | AH7: 04.02.2025 | AI7: 08:52 | AJ7: Ikke sjekket inn | AK7: Betaling nr: 1 (PAID) Beløp: 0,- | AL7: 000000000 | AM7: 9826897 | AP7: Nei | AQ7: Ja
A8: Tiril | B8: Byrkjeland | C8: bar-mart@online.no | D8: Norge | E8: NOR | F8: 24.01.2014 | G8: 11 år | H8: +4748115054 | I8: K | J8: IL i BUL Tromsø | K8: 28037 | L8: 58354 | M8: Troms friidrettskrets | N8: 555 | P8: Friidrett på bane | Q8: Kule | R8: Jenter 11 | S8: 24.02.2025 | T8: 17:00 | U8: 0 | V8: 0 | W8: N | Z8: Frode Byrkjeland | AA8: frodebyrkjeland25@gmail.com | AB8: 0 | AC8: 0 | AD8: Ja | AF8: cm6r1rx7n02h69o01ixsjs4vr | AG8: Påmeldt | AH8: 04.02.2025 | AI8: 23:26 | AJ8: Ikke sjekket inn | AK8: Betaling nr: 1 (PAID) Beløp: 0,- | AL8: 139233290 | AM8: 9410734 | AP8: Nei | AQ8: Ja
A9: Tiril | B9: Byrkjeland | C9: bar-mart@online.no | D9: Norge | E9: NOR | F9: 24.01.2014 | G9: 11 år | H9: +4748115054 | I9: K | J9: IL i BUL Tromsø | K9: 28037 | L9: 58354 | M9: Troms friidrettskrets | N9: 555 | P9: Friidrett på bane | Q9: Høyde | R9: Jenter 11 | S9: 24.02.2025 | T9: 17:00 | U9: 0 | V9: 0 | W9: N | Z9: Frode Byrkjeland | AA9: frodebyrkjeland25@gmail.com | AB9: 0 | AC9: 0 | AD9: Ja | AF9: cm6r1rx7n02h69o01ixsjs4vr | AG9: Påmeldt | AH9: 04.02.2025 | AI9: 23:26 | AJ9: Ikke sjekket inn | AK9: Betaling nr: 1 (PAID) Beløp: 0,- | AL9: 139233290 | AM9: 9410734 | AP9: Nei | AQ9: Ja
A10: Tiril | B10: Byrkjeland | C10: bar-mart@online.no | D10: Norge | E10: NOR | F10: 24.01.2014 | G10: 11 år | H10: +4748115054 | I10: K | J10: IL i BUL Tromsø | K10: 28037 | L10: 58354 | M10: Troms friidrettskrets | N10: 555 | P10: Friidrett på bane | Q10: 600 meter | R10: Jenter 11 | S10: 24.02.2025 | T10: 17:00 | U10: 0 | V10: 0 | W10: N | Z10: Frode Byrkjeland | AA10: frodebyrkjeland25@gmail.com | AB10: 0 | AC10: 0 | AD10: Ja | AF10: cm6r1rx7n02h69o01ixsjs4vr | AG10: Påmeldt | AH10: 04.02.2025 | AI10: 23:26 | AJ10: Ikke sjekket inn | AK10: Betaling nr: 1 (PAID) Beløp: 0,- | AL10: 139233290 | AM10: 9410734 | AP10: Nei | AQ10: Ja
A11: Ola | B11: Kuttner | C11: samuel.kuttner@gmail.com | D11: Norge | E11: NOR | F11: 01.01.2015 | G11: 10 år | H11: +4741087110 | I11: M | J11: IL i BUL Tromsø | K11: 28037 | L11: 58354 | M11: Troms friidrettskrets | N11: 555 | P11: Friidrett på bane | Q11: 300 meter | R11: Gutter 10 | S11: 24.02.2025 | T11: 17:00 | U11: 0 | V11: 0 | W11: N | Z11: Samuel Kuttner | AA11: samuel.kuttner@gmail.com | AB11: 0 | AC11: 0 | AD11: Ja | AF11: cm6vdwsxl01xkco011ypzcepo | AG11: Påmeldt | AH11: 08.02.2025 | AI11: 00:16 | AJ11: Ikke sjekket inn | AK11: Betaling nr: 1 (PAID) Beløp: 0,- | AL11: 000000000 | AM11: 7838327 | AP11: Nei | AQ11: Ja
A12: Ola | B12: Kuttner | C12: samuel.kuttner@gmail.com | D12: Norge | E12: NOR | F12: 01.01.2015 | G12: 10 år | H12: +4741087110 | I12: M | J12: IL i BUL Tromsø | K12: 28037 | L12: 58354 | M12: Troms friidrettskrets | N12: 555 | P12: Friidrett på bane | Q12: Høyde | R12: Gutter 10 | S12: 24.02.2025 | T12: 17:00 | U12: 0 | V12: 0 | W12: N | Z12: Samuel Kuttner | AA12: samuel.kuttner@gmail.com | AB12: 0 | AC12: 0 | AD12: Ja | AF12: cm6vdwsxl01xkco011ypzcepo | AG12: Påmeldt | AH12: 08.02.2025 | AI12: 00:16 | AJ12: Ikke sjekket inn | AK12: Betaling nr: 1 (PAID) Beløp: 0,- | AL12: 000000000 | AM12: 7838327 | AP12: Nei | AQ12: Ja
A13: Ola | B13: Kuttner | C13: samuel.kuttner@gmail.com | D13: Norge | E13: NOR | F13: 01.01.2015 | G13: 10 år | H13: +4741087110 | I13: M | J13: IL i BUL Tromsø | K13: 28037 | L13: 58354 | M13: Troms friidrettskrets | N13: 555 | P13: Friidrett på bane | Q13: Kule | R13: Gutter 10 | S13: 24.02.2025 | T13: 17:00 | U13: 0 | V13: 0 | W13: N | Z13: Samuel Kuttner | AA13: samuel.kuttner@gmail.com | AB13: 0 | AC13: 0 | AD13: Ja | AF13: cm6vdwsxl01xkco011ypzcepo | AG13: Påmeldt | AH13: 08.02.2025 | AI13: 00:16 | AJ13: Ikke sjekket inn | AK13: Betaling nr: 1 (PAID) Beløp: 0,- | AL13: 000000000 | AM13: 7838327 | AP13: Nei | AQ13: Ja
... A22: Karl Christian | B22: Kvistad-Thomassen | C22: karlm_t@hotmail.com | D22: Norge | E22: NOR | F22: 02.05.2018 | G22: 6 år | H22: +4793262780 | I22: M | J22: IL i BUL Tromsø | K22: 28037 | L22: 58354 | M22: Troms friidrettskrets | N22: 555 | P22: Friidrett på bane | Q22: Kule | R22: Gutter 10 | S22: 24.02.2025 | T22: 17:00 | U22: 0 | V22: 0 | W22: N | Z22: Karl Martin Thomassen | AA22: karlm_t@hotmail.com | AB22: 0 | AC22: 0 | AD22: Ja | AF22: cm71wj2iw096udw013fmpxhh4 | AG22: Påmeldt | AH22: 12.02.2025 | AI22: 13:44 | AJ22: Ikke sjekket inn | AK22: Betaling nr: 1 (PAID) Beløp: 0,- | AL22: 000000000 | AM22: 10235269 | AP22: Nei | AQ22: Nei
A23: Elsa Mækelæ | B23: Lindblad | C23: elsa.m.lindblad@icloud.com | D23: Norge | E23: NOR | F23: 17.01.2011 | G23: 14 år | H23: +4794971390 | I23: K | J23: IL i BUL Tromsø | K23: 28037 | L23: 58354 | M23: Troms friidrettskrets | N23: 555 | P23: Friidrett på bane | Q23: Lengde | R23: Jenter 14 | S23: 24.02.2025 | T23: 17:00 | U23: 0 | V23: 0 | W23: J | X23: 201809 | Z23: Martin Mækelæ Lindblad | AA23: martin-lindblad@hotmail.com | AB23: 0 | AC23: 0 | AD23: Ja | AF23: cm72csnp103ibc301089nlu8y | AG23: Påmeldt | AH23: 12.02.2025 | AI23: 21:19 | AJ23: Ikke sjekket inn | AK23: Betaling nr: 1 (PAID) Beløp: 0,- | AL23: 144479219 | AM23: 8878122 | AP23: Nei | AQ23: Ja
A24: Elsa Mækelæ | B24: Lindblad | C24: elsa.m.lindblad@icloud.com | D24: Norge | E24: NOR | F24: 17.01.2011 | G24: 14 år | H24: +4794971390 | I24: K | J24: IL i BUL Tromsø | K24: 28037 | L24: 58354 | M24: Troms friidrettskrets | N24: 555 | P24: Friidrett på bane | Q24: Kule | R24: Jenter 14 | S24: 24.02.2025 | T24: 17:00 | U24: 0 | V24: 0 | W24: J | X24: 201809 | Z24: Martin Mækelæ Lindblad | AA24: martin-lindblad@hotmail.com | AB24: 0 | AC24: 0 | AD24: Ja | AF24: cm72csnp103ibc301089nlu8y | AG24: Påmeldt | AH24: 12.02.2025 | AI24: 21:19 | AJ24: Ikke sjekket inn | AK24: Betaling nr: 1 (PAID) Beløp: 0,- | AL24: 144479219 | AM24: 8878122 | AP24: Nei | AQ24: Ja
A25: Elsa Mækelæ | B25: Lindblad | C25: elsa.m.lindblad@icloud.com | D25: Norge | E25: NOR | F25: 17.01.2011 | G25: 14 år | H25: +4794971390 | I25: K | J25: IL i BUL Tromsø | K25: 28037 | L25: 58354 | M25: Troms friidrettskrets | N25: 555 | P25: Friidrett på bane | Q25: 600 meter | R25: Jenter 14 | S25: 24.02.2025 | T25: 17:00 | U25: 0 | V25: 0 | W25: J | X25: 201809 | Z25: Martin Mækelæ Lindblad | AA25: martin-lindblad@hotmail.com | AB25: 0 | AC25: 0 | AD25: Ja | AF25: cm72csnp103ibc301089nlu8y | AG25: Påmeldt | AH25: 12.02.2025 | AI25: 21:19 | AJ25: Ikke sjekket inn | AK25: Betaling nr: 1 (PAID) Beløp: 0,- | AL25: 144479219 | AM25: 8878122 | AP25: Nei | AQ25: Ja
A26: Lea Johansen | B26: Maisenhølder | C26: goerilj@hotmail.com | D26: Norge | E26: NOR | F26: 22.07.2014 | G26: 10 år | H26: +4748147944 | I26: K | J26: IL i BUL Tromsø | K26: 28037 | L26: 58354 | M26: Troms friidrettskrets | N26: 555 | P26: Friidrett på bane | Q26: 600 meter | R26: Jenter 11 | S26: 24.02.2025 | T26: 17:00 | U26: 0 | V26: 0 | W26: N | Z26: Gøril Johansen | AA26: goerilj@hotmail.com | AB26: 0 | AC26: 0 | AD26: Ja | AF26: cm74dsal404y8ab014iloqt6g | AG26: Påmeldt | AH26: 14.02.2025 | AI26: 07:22 | AJ26: Ikke sjekket inn | AK26: Betaling nr: 1 (PAID) Beløp: 0,- | AL26: 000000000 | AM26: 9774141 | AP26: Nei | AQ26: Ja
A27: Lea Johansen | B27: Maisenhølder | C27: goerilj@hotmail.com | D27: Norge | E27: NOR | F27: 22.07.2014 | G27: 10 år | H27: +4748147944 | I27: K | J27: IL i BUL Tromsø | K27: 28037 | L27: 58354 | M27: Troms friidrettskrets | N27: 555 | P27: Friidrett på bane | Q27: Høyde | R27: Jenter 11 | S27: 24.02.2025 | T27: 17:00 | U27: 0 | V27: 0 | W27: N | Z27: Gøril Johansen | AA27: goerilj@hotmail.com | AB27: 0 | AC27: 0 | AD27: Ja | AF27: cm74dsal404y8ab014iloqt6g | AG27: Påmeldt | AH27: 14.02.2025 | AI27: 07:22 | AJ27: Ikke sjekket inn | AK27: Betaling nr: 1 (PAID) Beløp: 0,- | AL27: 000000000 | AM27: 9774141 | AP27: Nei | AQ27: Ja
A28: Lea Johansen | B28: Maisenhølder | C28: goerilj@hotmail.com | D28: Norge | E28: NOR | F28: 22.07.2014 | G28: 10 år | H28: +4748147944 | I28: K | J28: IL i BUL Tromsø | K28: 28037 | L28: 58354 | M28: Troms friidrettskrets | N28: 555 | P28: Friidrett på bane | Q28: Kule | R28: Jenter 11 | S28: 24.02.2025 | T28: 17:00 | U28: 0 | V28: 0 | W28: N | Z28: Gøril Johansen | AA28: goerilj@hotmail.com | AB28: 0 | AC28: 0 | AD28: Ja | AF28: cm74dsal404y8ab014iloqt6g | AG28: Påmeldt | AH28: 14.02.2025 | AI28: 07:22 | AJ28: Ikke sjekket inn | AK28: Betaling nr: 1 (PAID) Beløp: 0,- | AL28: 000000000 | AM28: 9774141 | AP28: Nei | AQ28: Ja
A29: Robert | B29: Hennoch | C29: sheilahennoch@hotmail.com | D29: Estland | E29: EST | F29: 06.06.2017 | G29: 7 år | H29: +4748044676 | I29: M | J29: IL i BUL Tromsø | K29: 28037 | L29: 58354 | M29: Troms friidrettskrets | N29: 555 | P29: Friidrett på bane | Q29: Høyde | R29: Gutter 10 | S29: 24.02.2025 | T29: 17:00 | U29: 0 | V29: 0 | W29: N | Z29: Sheila Hennoch | AA29: sheilahennoch@hotmail.com | AB29: 0 | AC29: 0 | AD29: Ja | AF29: cm74jqbjb05an7x01irp6xwpq | AG29: Påmeldt | AH29: 14.02.2025 | AI29: 10:08 | AJ29: Ikke sjekket inn | AK29: Betaling nr: 1 (PAID) Beløp: 0,- | AL29: 000000000 | AM29: 9779787 | AP29: Nei | AQ29: Ja
A30: Robert | B30: Hennoch | C30: sheilahennoch@hotmail.com | D30: Estland | E30: EST | F30: 06.06.2017 | G30: 7 år | H30: +4748044676 | I30: M | J30: IL i BUL Tromsø | K30: 28037 | L30: 58354 | M30: Troms friidrettskrets | N30: 555 | P30: Friidrett på bane | Q30: Kule | R30: Gutter 10 | S30: 24.02.2025 | T30: 17:00 | U30: 0 | V30: 0 | W30: N | Z30: Sheila Hennoch | AA30: sheilahennoch@hotmail.com | AB30: 0 | AC30: 0 | AD30: Ja | AF30: cm74jqbjb05an7x01irp6xwpq | AG30: Påmeldt | AH30: 14.02.2025 | AI30: 10:08 | AJ30: Ikke sjekket inn | AK30: Betaling nr: 1 (PAID) Beløp: 0,- | AL30: 000000000 | AM30: 9779787 | AP30: Nei | AQ30: Ja
A31: Magnus Somying | B31: Olsen | C31: olsoma09@gmail.com | D31: Norge | E31: NOR | F31: 03.06.2009 | G31: 15 år | H31: +4795528655 | I31: M | J31: IL i BUL Tromsø | K31: 28037 | L31: 58354 | M31: Troms friidrettskrets | N31: 555 | P31: Friidrett på bane | Q31: 600 meter | R31: Gutter 16 | S31: 24.02.2025 | T31: 17:00 | U31: 0 | V31: 0 | W31: J | X31: 201037 | Z31: Magnus Somying Olsen | AA31: olsoma09@gmail.com | AB31: 0 | AC31: 0 | AD31: Ja | AF31: cm77tyfge0eo2ab01m7azk0ji | AG31: Påmeldt | AH31: 16.02.2025 | AI31: 17:18 | AJ31: Ikke sjekket inn | AK31: Betaling nr: 1 (PAID) Beløp: 0,- | AL31: 130509680 | AM31: 8273202 | AP31: Nei | AQ31: Ja
A32: Magnus Somying | B32: Olsen | C32: olsoma09@gmail.com | D32: Norge | E32: NOR | F32: 03.06.2009 | G32: 15 år | H32: +4795528655 | I32: M | J32: IL i BUL Tromsø | K32: 28037 | L32: 58354 | M32: Troms friidrettskrets | N32: 555 | P32: Friidrett på bane | Q32: Lengde | R32: Gutter 16 | S32: 24.02.2025 | T32: 17:00 | U32: 0 | V32: 0 | W32: J | X32: 201037 | Z32: Magnus Somying Olsen | AA32: olsoma09@gmail.com | AB32: 0 | AC32: 0 | AD32: Ja | AF32: cm77tyfge0eo2ab01m7azk0ji | AG32: Påmeldt | AH32: 16.02.2025 | AI32: 17:18 | AJ32: Ikke sjekket inn | AK32: Betaling nr: 1 (PAID) Beløp: 0,- | AL32: 130509680 | AM32: 8273202 | AP32: Nei | AQ32: Ja
A33: Filip | B33: Flaa | C33: seijampedersen@gmail.com | D33: Norge | E33: NOR | F33: 18.12.2014 | G33: 10 år | H33: +4747647319 | I33: M | J33: IL i BUL Tromsø | K33: 28037 | L33: 58354 | M33: Troms friidrettskrets | N33: 555 | P33: Friidrett på bane | Q33: 600 meter | R33: Gutter 11 | S33: 24.02.2025 | T33: 17:00 | U33: 0 | V33: 0 | W33: N | Z33: Seija Maria Pedersen | AA33: seijampedersen@gmail.com | AB33: 0 | AC33: 0 | AD33: Ja | AF33: cm77uqhnu0eu77x01mi1kll61 | AG33: Påmeldt | AH33: 16.02.2025 | AI33: 17:41 | AJ33: Ikke sjekket inn | AK33: Betaling nr: 1 (PAID) Beløp: 0,- | AL33: 000000000 | AM33: 9820932 | AP33: Nei | AQ33: Ja
A34: Filip | B34: Flaa | C34: seijampedersen@gmail.com | D34: Norge | E34: NOR | F34: 18.12.2014 | G34: 10 år | H34: +4747647319 | I34: M | J34: IL i BUL Tromsø | K34: 28037 | L34: 58354 | M34: Troms friidrettskrets | N34: 555 | P34: Friidrett på bane | Q34: Høyde | R34: Gutter 11 | S34: 24.02.2025 | T34: 17:00 | U34: 0 | V34: 0 | W34: N | Z34: Seija Maria Pedersen | AA34: seijampedersen@gmail.com | AB34: 0 | AC34: 0 | AD34: Ja | AF34: cm77uqhnu0eu77x01mi1kll61 | AG34: Påmeldt | AH34: 16.02.2025 | AI34: 17:41 | AJ34: Ikke sjekket inn | AK34: Betaling nr: 1 (PAID) Beløp: 0,- | AL34: 000000000 | AM34: 9820932 | AP34: Nei | AQ34: Ja
A35: Jakob | B35: Flaa | C35: seijampedersen@gmail.com | D35: Norge | E35: NOR | F35: 28.03.2016 | G35: 8 år | H35: +4747647319 | I35: M | J35: IL i BUL Tromsø | K35: 28037 | L35: 58354 | M35: Troms friidrettskrets | N35: 555 | P35: Friidrett på bane | Q35: 300 meter | R35: Gutter 10 | S35: 24.02.2025 | T35: 17:00 | U35: 0 | V35: 0 | W35: N | Z35: Seija Maria Pedersen | AA35: seijampedersen@gmail.com | AB35: 0 | AC35: 0 | AD35: Ja | AF35: cm77uqhnu0eu77x01mi1kll61 | AG35: Påmeldt | AH35: 16.02.2025 | AI35: 17:41 | AJ35: Ikke sjekket inn | AK35: Betaling nr: 1 (PAID) Beløp: 0,- | AL35: 000000000 | AM35: 9977934 | AP35: Nei | AQ35: Ja
A36: Jakob | B36: Flaa | C36: seijampedersen@gmail.com | D36: Norge | E36: NOR | F36: 28.03.2016 | G36: 8 år | H36: +4747647319 | I36: M | J36: IL i BUL Tromsø | K36: 28037 | L36: 58354 | M36: Troms friidrettskrets | N36: 555 | P36: Friidrett på bane | Q36: Høyde | R36: Gutter 10 | S36: 24.02.2025 | T36: 17:00 | U36: 0 | V36: 0 | W36: N | Z36: Seija Maria Pedersen | AA36: seijampedersen@gmail.com | AB36: 0 | AC36: 0 | AD36: Ja | AF36: cm77uqhnu0eu77x01mi1kll61 | AG36: Påmeldt | AH36: 16.02.2025 | AI36: 17:41 | AJ36: Ikke sjekket inn | AK36: Betaling nr: 1 (PAID) Beløp: 0,- | AL36: 000000000 | AM36: 9977934 | AP36: Nei | AQ36: Ja
A37: Einar | B37: Hallanger | C37: audunp@gmail.com | D37: Norge | E37: NOR | F37: 30.12.2013 | G37: 11 år | H37: +4745454690 | I37: M | J37: IL i BUL Tromsø | K37: 28037 | L37: 58354 | M37: Troms friidrettskrets | N37: 555 | P37: Friidrett på bane | Q37: 600 meter | R37: Gutter 12 | S37: 24.02.2025 | T37: 17:00 | U37: 0 | V37: 0 | W37: N | Z37: Audun Pedersen | AA37: audunp@gmail.com | AB37: 0 | AC37: 0 | AD37: Ja | AF37: cm77v0wo60evw7x01rb9587rm | AG37: Påmeldt | AH37: 16.02.2025 | AI37: 17:48 | AJ37: Ikke sjekket inn | AK37: Betaling nr: 1 (PAID) Beløp: 0,- | AL37: 000000000 | AM37: 9652656 | AP37: Nei | AQ37: Ja
A38: Einar | B38: Hallanger | C38: audunp@gmail.com | D38: Norge | E38: NOR | F38: 30.12.2013 | G38: 11 år | H38: +4745454690 | I38: M | J38: IL i BUL Tromsø | K38: 28037 | L38: 58354 | M38: Troms friidrettskrets | N38: 555 | P38: Friidrett på bane | Q38: Høyde | R38: Gutter 12 | S38: 24.02.2025 | T38: 17:00 | U38: 0 | V38: 0 | W38: N | Z38: Audun Pedersen | AA38: audunp@gmail.com | AB38: 0 | AC38: 0 | AD38: Ja | AF38: cm77v0wo60evw7x01rb9587rm | AG38: Påmeldt | AH38: 16.02.2025 | AI38: 17:48 | AJ38: Ikke sjekket inn | AK38: Betaling nr: 1 (PAID) Beløp: 0,- | AL38: 000000000 | AM38: 9652656 | AP38: Nei | AQ38: Ja
A39: Aurora Molund | B39: Tangen | C39: aurora.molund.tangen@icloud.com | D39: Norge | E39: NOR | F39: 13.07.2009 | G39: 15 år | H39: +4791004024 | I39: K | J39: IL i BUL Tromsø | K39: 28037 | L39: 58354 | M39: Troms friidrettskrets | N39: 555 | P39: Friidrett på bane | Q39: 600 meter | R39: Jenter 16 | S39: 24.02.2025 | T39: 17:00 | U39: 0 | V39: 0 | W39: J | X39: 201546 | Z39: Brita Fagernes Molund | AA39: britafm@yahoo.com | AB39: 0 | AC39: 0 | AD39: Ja | AF39: cm77yc30j0fmt7x01l4sustj3 | AG39: Påmeldt | AH39: 16.02.2025 | AI39: 19:22 | AJ39: Ikke sjekket inn | AK39: Betaling nr: 1 (PAID) Beløp: 0,- | AL39: 133032235 | AM39: 6980701 | AP39: Nei | AQ39: Nei
A40: Aurora Molund | B40: Tangen | C40: aurora.molund.tangen@icloud.com | D40: Norge | E40: NOR | F40: 13.07.2009 | G40: 15 år | H40: +4791004024 | I40: K | J40: IL i BUL Tromsø | K40: 28037 | L40: 58354 | M40: Troms friidrettskrets | N40: 555 | P40: Friidrett på bane | Q40: Lengde | R40: Jenter 16 | S40: 24.02.2025 | T40: 17:00 | U40: 0 | V40: 0 | W40: J | X40: 201546 | Z40: Brita Fagernes Molund | AA40: britafm@yahoo.com | AB40: 0 | AC40: 0 | AD40: Ja | AF40: cm77yc30j0fmt7x01l4sustj3 | AG40: Påmeldt | AH40: 16.02.2025 | AI40: 19:22 | AJ40: Ikke sjekket inn | AK40: Betaling nr: 1 (PAID) Beløp: 0,- | AL40: 133032235 | AM40: 6980701 | AP40: Nei | AQ40: Nei
A41: Leonard Aleksander | B41: Hausner | C41: leohau12009@gmail.com | D41: Norge | E41: NOR | F41: 20.07.2009 | G41: 15 år | H41: +4748436334 | I41: M | J41: IL i BUL Tromsø | K41: 28037 | L41: 58354 | M41: Troms friidrettskrets | N41: 555 | P41: Friidrett på bane | Q41: 600 meter | R41: Gutter 16 | S41: 24.02.2025 | T41: 17:00 | U41: 0 | V41: 0 | W41: J | X41: 202097 | Z41: Karianne Guttormsen Olsen | AA41: karianne.olsen@hotmail.com | AB41: 0 | AC41: 0 | AD41: Ja | AF41: cm77ygc5n0fno7x01sngfeiqn | AG41: Påmeldt | AH41: 16.02.2025 | AI41: 19:27 | AJ41: Ikke sjekket inn | AK41: Betaling nr: 1 (PAID) Beløp: 0,- | AL41: 139230114 | AM41: 7118250 | AP41: Ja | AQ41: Ja
A42: Leonard Aleksander | B42: Hausner | C42: leohau12009@gmail.com | D42: Norge | E42: NOR | F42: 20.07.2009 | G42: 15 år | H42: +4748436334 | I42: M | J42: IL i BUL Tromsø | K42: 28037 | L42: 58354 | M42: Troms friidrettskrets | N42: 555 | P42: Friidrett på bane | Q42: Lengde | R42: Gutter 16 | S42: 24.02.2025 | T42: 17:00 | U42: 0 | V42: 0 | W42: J | X42: 202097 | Z42: Karianne Guttormsen Olsen | AA42: karianne.olsen@hotmail.com | AB42: 0 | AC42: 0 | AD42: Ja | AF42: cm77ygc5n0fno7x01sngfeiqn | AG42: Påmeldt | AH42: 16.02.2025 | AI42: 19:27 | AJ42: Ikke sjekket inn | AK42: Betaling nr: 1 (PAID) Beløp: 0,- | AL42: 139230114 | AM42: 7118250 | AP42: Ja | AQ42: Ja
A43: Leonard Aleksander | B43: Hausner | C43: leohau12009@gmail.com | D43: Norge | E43: NOR | F43: 20.07.2009 | G43: 15 år | H43: +4748436334 | I43: M | J43: IL i BUL Tromsø | K43: 28037 | L43: 58354 | M43: Troms friidrettskrets | N43: 555 | P43: Friidrett på bane | Q43: Kule | R43: Gutter 16 | S43: 24.02.2025 | T43: 17:00 | U43: 0 | V43: 0 | W43: J | X43: 202097 | Z43: Karianne Guttormsen Olsen | AA43: karianne.olsen@hotmail.com | AB43: 0 | AC43: 0 | AD43: Ja | AF43: cm77ygc5n0fno7x01sngfeiqn | AG43: Påmeldt | AH43: 16.02.2025 | AI43: 19:27 | AJ43: Ikke sjekket inn | AK43: Betaling nr: 1 (PAID) Beløp: 0,- | AL43: 139230114 | AM43: 7118250 | AP43: Ja | AQ43: Ja
A44: Kolbjørn | B44: Baade | C44: lranveig@gmail.com | D44: Norge | E44: NOR | F44: 15.05.2011 | G44: 13 år | H44: +4793042802 | I44: M | J44: IL i BUL Tromsø | K44: 28037 | L44: 58354 | M44: Troms friidrettskrets | N44: 555 | P44: Friidrett på bane | Q44: Kule | R44: Gutter 14 | S44: 24.02.2025 | T44: 17:00 | U44: 0 | V44: 0 | W44: J | X44: 198689 | Z44: Kolbjørn Baade | AA44: lranveig@gmail.com | AB44: 0 | AC44: 0 | AD44: Ja | AF44: cm77yhzy00fo77x01l5bjjvvw | AG44: Påmeldt | AH44: 16.02.2025 | AI44: 19:26 | AJ44: Ikke sjekket inn | AK44: Betaling nr: 1 (PAID) Beløp: 0,- | AL44: 135475176 | AM44: 8192558 | AP44: Nei | AQ44: Ja
A45: Kolbjørn | B45: Baade | C45: lranveig@gmail.com | D45: Norge | E45: NOR | F45: 15.05.2011 | G45: 13 år | H45: +4793042802 | I45: M | J45: IL i BUL Tromsø | K45: 28037 | L45: 58354 | M45: Troms friidrettskrets | N45: 555 | P45: Friidrett på bane | Q45: Lengde | R45: Gutter 14 | S45: 24.02.2025 | T45: 17:00 | U45: 0 | V45: 0 | W45: J | X45: 198689 | Z45: Kolbjørn Baade | AA45: lranveig@gmail.com | AB45: 0 | AC45: 0 | AD45: Ja | AF45: cm77yhzy00fo77x01l5bjjvvw | AG45: Påmeldt | AH45: 16.02.2025 | AI45: 19:26 | AJ45: Ikke sjekket inn | AK45: Betaling nr: 1 (PAID) Beløp: 0,- | AL45: 135475176 | AM45: 8192558 | AP45: Nei | AQ45: Ja
A46: Kolbjørn | B46: Baade | C46: lranveig@gmail.com | D46: Norge | E46: NOR | F46: 15.05.2011 | G46: 13 år | H46: +4793042802 | I46: M | J46: IL i BUL Tromsø | K46: 28037 | L46: 58354 | M46: Troms friidrettskrets | N46: 555 | P46: Friidrett på bane | Q46: 600 meter | R46: Gutter 14 | S46: 24.02.2025 | T46: 17:00 | U46: 0 | V46: 0 | W46: J | X46: 198689 | Z46: Kolbjørn Baade | AA46: lranveig@gmail.com | AB46: 0 | AC46: 0 | AD46: Ja | AF46: cm77yhzy00fo77x01l5bjjvvw | AG46: Påmeldt | AH46: 16.02.2025 | AI46: 19:26 | AJ46: Ikke sjekket inn | AK46: Betaling nr: 1 (PAID) Beløp: 0,- | AL46: 135475176 | AM46: 8192558 | AP46: Nei | AQ46: Ja
A47: Noomi Linnea | B47: Olsen | C47: kimols1@gmail.com | D47: Norge | E47: NOR | F47: 14.04.2018 | G47: 6 år | H47: +4791882048 | I47: K | J47: IL i BUL Tromsø | K47: 28037 | L47: 58354 | M47: Troms friidrettskrets | N47: 555 | P47: Friidrett på bane | Q47: 300 meter | R47: Jenter 10 | S47: 24.02.2025 | T47: 17:00 | U47: 0 | V47: 0 | W47: N | Z47: Kim Olsen | AA47: kimols1@gmail.com | AB47: 0 | AC47: 0 | AD47: Ja | AF47: cm783auu90gzxab01qj82hf0j | AG47: Påmeldt | AH47: 16.02.2025 | AI47: 21:40 | AJ47: Ikke sjekket inn | AK47: Betaling nr: 1 (PAID) Beløp: 0,- | AL47: 000000000 | AM47: 9623729 | AP47: Nei | AQ47: Ja
A48: Noomi Linnea | B48: Olsen | C48: kimols1@gmail.com | D48: Norge | E48: NOR | F48: 14.04.2018 | G48: 6 år | H48: +4791882048 | I48: K | J48: IL i BUL Tromsø | K48: 28037 | L48: 58354 | M48: Troms friidrettskrets | N48: 555 | P48: Friidrett på bane | Q48: Høyde | R48: Jenter 10 | S48: 24.02.2025 | T48: 17:00 | U48: 0 | V48: 0 | W48: N | Z48: Kim Olsen | AA48: kimols1@gmail.com | AB48: 0 | AC48: 0 | AD48: Ja | AF48: cm783auu90gzxab01qj82hf0j | AG48: Påmeldt | AH48: 16.02.2025 | AI48: 21:40 | AJ48: Ikke sjekket inn | AK48: Betaling nr: 1 (PAID) Beløp: 0,- | AL48: 000000000 | AM48: 9623729 | AP48: Nei | AQ48: Ja
...

Sheet Sheet2
A1: 24.02.2025
B3: 60 meter hekk | C3: 80 meter hekk | D3: 100 meter hekk | E3: 110 meter hekk | F3: 200 meter hekk | G3: 300 meter hekk | H3: 400 meter hekk | I3: 60 meter | J3: 100 meter | K3: 200 meter | L3: 300 meter | M3: 400 meter | N3: 600 meter | O3: 800 meter | P3: 1500 meter | Q3: 3000 meter | R3: 5000 meter | S3: Lengde | T3: Tresteg | U3: Høyde | V3: Stav | W3: Liten ball | X3: Kule | Y3: Slegge | Z3: Diskos | AA3: Spyd
A4: FIFA | B4: 0 | C4: 0 | D4: 0 | E4: 0 | F4: 0 | G4: 0 | H4: 0 | I4: 0 | J4: 0 | K4: 0 | L4: 0 | M4: 0 | N4: 0 | O4: 0 | P4: 0 | Q4: 0 | R4: 0 | S4: 0 | T4: 0 | U4: 0 | V4: 0 | W4: 0 | X4: 0 | Y4: 0 | Z4: 0 | AA4: 0
A6: Gutter 10 | B6: =COUNTIFS(Sheet1!$R:$R,$A6,Sheet1!$S:$S,$A$1,Sheet1!$Q:$Q,B$3) -> 0 | C6: =COUNTIFS(Sheet1!$R:$R,$A6,Sheet1!$S:$S,$A$1,Sheet1!$Q:$Q,C$3) -> 0 | D6: =COUNTIFS(Sheet1!$R:$R,$A6,Sheet1!$S:$S,$A$1,Sheet1!$Q:$Q,D$3) -> 0 | E6: =COUNTIFS(Sheet1!$R:$R,$A6,Sheet1!$S:$S,$A$1,Sheet1!$Q:$Q,E$3) -> 0 | F6: =COUNTIFS(Sheet1!$R:$R,$A6,Sheet1!$S:$S,$A$1,Sheet1!$Q:$Q,F$3) -> 0 | G6: =COUNTIFS(Sheet1!$R:$R,$A6,Sheet1!$S:$S,$A$1,Sheet1!$Q:$Q,G$3) -> 0 | H6: =COUNTIFS(Sheet1!$R:$R,$A6,Sheet1!$S:$S,$A$1,Sheet1!$Q:$Q,H$3) -> 0 | I6: =COUNTIFS(Sheet1!$R:$R,$A6,Sheet1!$S:$S,$A$1,Sheet1!$Q:$Q,I$3) -> 0 | ... AA6: =COUNTIFS(Sheet1!$R:$R,$A6,Sheet1!$S:$S,$A$1,Sheet1!$Q:$Q,AA$3) -> 0
A7: Gutter 11 | B7: =COUNTIFS(Sheet1!$R:$R,$A7,Sheet1!$S:$S,$A$1,Sheet1!$Q:$Q,B$3) -> 0 | C7: =COUNTIFS(Sheet1!$R:$R,$A7,Sheet1!$S:$S,$A$1,Sheet1!$Q:$Q,C$3) -> 0 | D7: =COUNTIFS(Sheet1!$R:$R,$A7,Sheet1!$S:$S,$A$1,Sheet1!$Q:$Q,D$3) -> 0 | E7: =COUNTIFS(Sheet1!$R:$R,$A7,Sheet1!$S:$S,$A$1,Sheet1!$Q:$Q,E$3) -> 0 | F7: =COUNTIFS(Sheet1!$R:$R,$A7,Sheet1!$S:$S,$A$1,Sheet1!$Q:$Q,F$3) -> 0 | G7: =COUNTIFS(Sheet1!$R:$R,$A7,Sheet1!$S:$S,$A$1,Sheet1!$Q:$Q,G$3) -> 0 | H7: =COUNTIFS(Sheet1!$R:$R,$A7,Sheet1!$S:$S,$A$1,Sheet1!$Q:$Q,H$3) -> 0 | I7: =COUNTIFS(Sheet1!$R:$R,$A7,Sheet1!$S:$S,$A$1,Sheet1!$Q:$Q,I$3) -> 0 | ... AA7: =COUNTIFS(Sheet1!$R:$R,$A7,Sheet1!$S:$S,$A$1,Sheet1!$Q:$Q,AA$3) -> 0
A8: Gutter 12 | B8: =COUNTIFS(Sheet1!$R:$R,$A8,Sheet1!$S:$S,$A$1,Sheet1!$Q:$Q,B$3) -> 0 | C8: =COUNTIFS(Sheet1!$R:$R,$A8,Sheet1!$S:$S,$A$1,Sheet1!$Q:$Q,C$3) -> 0 | D8: =COUNTIFS(Sheet1!$R:$R,$A8,Sheet1!$S:$S,$A$1,Sheet1!$Q:$Q,D$3) -> 0 | E8: =COUNTIFS(Sheet1!$R:$R,$A8,Sheet1!$S:$S,$A$1,Sheet1!$Q:$Q,E$3) -> 0 | F8: =COUNTIFS(Sheet1!$R:$R,$A8,Sheet1!$S:$S,$A$1,Sheet1!$Q:$Q,F$3) -> 0 | G8: =COUNTIFS(Sheet1!$R:$R,$A8,Sheet1!$S:$S,$A$1,Sheet1!$Q:$Q,G$3) -> 0 | H8: =COUNTIFS(Sheet1!$R:$R,$A8,Sheet1!$S:$S,$A$1,Sheet1!$Q:$Q,H$3) -> 0 | I8: =COUNTIFS(Sheet1!$R:$R,$A8,Sheet1!$S:$S,$A$1,Sheet1!$Q:$Q,I$3) -> 0 | ... AA8: =COUNTIFS(Sheet1!$R:$R,$A8,Sheet1!$S:$S,$A$1,Sheet1!$Q:$Q,AA$3) -> 0
A9: Gutter 13 | B9: =COUNTIFS(Sheet1!$R:$R,$A9,Sheet1!$S:$S,$A$1,Sheet1!$Q:$Q,B$3) -> 0 | C9: =COUNTIFS(Sheet1!$R:$R,$A9,Sheet1!$S:$S,$A$1,Sheet1!$Q:$Q,C$3) -> 0 | D9: =COUNTIFS(Sheet1!$R:$R,$A9,Sheet1!$S:$S,$A$1,Sheet1!$Q:$Q,D$3) -> 0 | E9: =COUNTIFS(Sheet1!$R:$R,$A9,Sheet1!$S:$S,$A$1,Sheet1!$Q:$Q,E$3) -> 0 | F9: =COUNTIFS(Sheet1!$R:$R,$A9,Sheet1!$S:$S,$A$1,Sheet1!$Q:$Q,F$3) -> 0 | G9: =COUNTIFS(Sheet1!$R:$R,$A9,Sheet1!$S:$S,$A$1,Sheet1!$Q:$Q,G$3) -> 0 | H9: =COUNTIFS(Sheet1!$R:$R,$A9,Sheet1!$S:$S,$A$1,Sheet1!$Q:$Q,H$3) -> 0 | I9: =COUNTIFS(Sheet1!$R:$R,$A9,Sheet1!$S:$S,$A$1,Sheet1!$Q:$Q,I$3) -> 0 | ... AA9: =COUNTIFS(Sheet1!$R:$R,$A9,Sheet1!$S:$S,$A$1,Sheet1!$Q:$Q,AA$3) -> 0
A10: Gutter 14 | B10: =COUNTIFS(Sheet1!$R:$R,$A10,Sheet1!$S:$S,$A$1,Sheet1!$Q:$Q,B$3) -> 0 | C10: =COUNTIFS(Sheet1!$R:$R,$A10,Sheet1!$S:$S,$A$1,Sheet1!$Q:$Q,C$3) -> 0 | D10: =COUNTIFS(Sheet1!$R:$R,$A10,Sheet1!$S:$S,$A$1,Sheet1!$Q:$Q,D$3) -> 0 | E10: =COUNTIFS(Sheet1!$R:$R,$A10,Sheet1!$S:$S,$A$1,Sheet1!$Q:$Q,E$3) -> 0 | F10: =COUNTIFS(Sheet1!$R:$R,$A10,Sheet1!$S:$S,$A$1,Sheet1!$Q:$Q,F$3) -> 0 | G10: =COUNTIFS(Sheet1!$R:$R,$A10,Sheet1!$S:$S,$A$1,Sheet1!$Q:$Q,G$3) -> 0 | H10: =COUNTIFS(Sheet1!$R:$R,$A10,Sheet1!$S:$S,$A$1,Sheet1!$Q:$Q,H$3) -> 0 | I10: =COUNTIFS(Sheet1!$R:$R,$A10,Sheet1!$S:$S,$A$1,Sheet1!$Q:$Q,I$3) -> 0 | ... AA10: =COUNTIFS(Sheet1!$R:$R,$A10,Sheet1!$S:$S,$A$1,Sheet1!$Q:$Q,AA$3) -> 0
A11: Gutter 15 | B11: =COUNTIFS(Sheet1!$R:$R,$A11,Sheet1!$S:$S,$A$1,Sheet1!$Q:$Q,B$3) -> 0 | C11: =COUNTIFS(Sheet1!$R:$R,$A11,Sheet1!$S:$S,$A$1,Sheet1!$Q:$Q,C$3) -> 0 | D11: =COUNTIFS(Sheet1!$R:$R,$A11,Sheet1!$S:$S,$A$1,Sheet1!$Q:$Q,D$3) -> 0 | E11: =COUNTIFS(Sheet1!$R:$R,$A11,Sheet1!$S:$S,$A$1,Sheet1!$Q:$Q,E$3) -> 0 | F11: =COUNTIFS(Sheet1!$R:$R,$A11,Sheet1!$S:$S,$A$1,Sheet1!$Q:$Q,F$3) -> 0 | G11: =COUNTIFS(Sheet1!$R:$R,$A11,Sheet1!$S:$S,$A$1,Sheet1!$Q:$Q,G$3) -> 0 | H11: =COUNTIFS(Sheet1!$R:$R,$A11,Sheet1!$S:$S,$A$1,Sheet1!$Q:$Q,H$3) -> 0 | I11: =COUNTIFS(Sheet1!$R:$R,$A11,Sheet1!$S:$S,$A$1,Sheet1!$Q:$Q,I$3) -> 0 | ... AA11: =COUNTIFS(Sheet1!$R:$R,$A11,Sheet1!$S:$S,$A$1,Sheet1!$Q:$Q,AA$3) -> 0
A12: Gutter 16 | B12: =COUNTIFS(Sheet1!$R:$R,$A12,Sheet1!$S:$S,$A$1,Sheet1!$Q:$Q,B$3) -> 0 | C12: =COUNTIFS(Sheet1!$R:$R,$A12,Sheet1!$S:$S,$A$1,Sheet1!$Q:$Q,C$3) -> 0 | D12: =COUNTIFS(Sheet1!$R:$R,$A12,Sheet1!$S:$S,$A$1,Sheet1!$Q:$Q,D$3) -> 0 | E12: =COUNTIFS(Sheet1!$R:$R,$A12,Sheet1!$S:$S,$A$1,Sheet1!$Q:$Q,E$3) -> 0 | F12: =COUNTIFS(Sheet1!$R:$R,$A12,Sheet1!$S:$S,$A$1,Sheet1!$Q:$Q,F$3) -> 0 | G12: =COUNTIFS(Sheet1!$R:$R,$A12,Sheet1!$S:$S,$A$1,Sheet1!$Q:$Q,G$3) -> 0 | H12: =COUNTIFS(Sheet1!$R:$R,$A12,Sheet1!$S:$S,$A$1,Sheet1!$Q:$Q,H$3) -> 0 | I12: =COUNTIFS(Sheet1!$R:$R,$A12,Sheet1!$S:$S,$A$1,Sheet1!$Q:$Q,I$3) -> 0 | ... AA12: =COUNTIFS(Sheet1!$R:$R,$A12,Sheet1!$S:$S,$A$1,Sheet1!$Q:$Q,AA$3) -> 0
A13: Gutter 17 | B13: =COUNTIFS(Sheet1!$R:$R,$A13,Sheet1!$S:$S,$A$1,Sheet1!$Q:$Q,B$3) -> 0 | C13: =COUNTIFS(Sheet1!$R:$R,$A13,Sheet1!$S:$S,$A$1,Sheet1!$Q:$Q,C$3) -> 0 | D13: =COUNTIFS(Sheet1!$R:$R,$A13,Sheet1!$S:$S,$A$1,Sheet1!$Q:$Q,D$3) -> 0 | E13: =COUNTIFS(Sheet1!$R:$R,$A13,Sheet1!$S:$S,$A$1,Sheet1!$Q:$Q,E$3) -> 0 | F13: =COUNTIFS(Sheet1!$R:$R,$A13,Sheet1!$S:$S,$A$1,Sheet1!$Q:$Q,F$3) -> 0 | G13: =COUNTIFS(Sheet1!$R:$R,$A13,Sheet1!$S:$S,$A$1,Sheet1!$Q:$Q,G$3) -> 0 | H13: =COUNTIFS(Sheet1!$R:$R,$A13,Sheet1!$S:$S,$A$1,Sheet1!$Q:$Q,H$3) -> 0 | I13: =COUNTIFS(Sheet1!$R:$R,$A13,Sheet1!$S:$S,$A$1,Sheet1!$Q:$Q,I$3) -> 0 | ... AA13: =COUNTIFS(Sheet1!$R:$R,$A13,Sheet1!$S:$S,$A$1,Sheet1!$Q:$Q,AA$3) -> 0
A14: Gutter 18-19 | B14: =COUNTIFS(Sheet1!$R:$R,$A14,Sheet1!$S:$S,$A$1,Sheet1!$Q:$Q,B$3) -> 0 | C14: =COUNTIFS(Sheet1!$R:$R,$A14,Sheet1!$S:$S,$A$1,Sheet1!$Q:$Q,C$3) -> 0 | D14: =COUNTIFS(Sheet1!$R:$R,$A14,Sheet1!$S:$S,$A$1,Sheet1!$Q:$Q,D$3) -> 0 | E14: =COUNTIFS(Sheet1!$R:$R,$A14,Sheet1!$S:$S,$A$1,Sheet1!$Q:$Q,E$3) -> 0 | F14: =COUNTIFS(Sheet1!$R:$R,$A14,Sheet1!$S:$S,$A$1,Sheet1!$Q:$Q,F$3) -> 0 | G14: =COUNTIFS(Sheet1!$R:$R,$A14,Sheet1!$S:$S,$A$1,Sheet1!$Q:$Q,G$3) -> 0 | H14: =COUNTIFS(Sheet1!$R:$R,$A14,Sheet1!$S:$S,$A$1,Sheet1!$Q:$Q,H$3) -> 0 | I14: =COUNTIFS(Sheet1!$R:$R,$A14,Sheet1!$S:$S,$A$1,Sheet1!$Q:$Q,I$3) -> 0 | ... AA14: =COUNTIFS(Sheet1!$R:$R,$A14,Sheet1!$S:$S,$A$1,Sheet1!$Q:$Q,AA$3) -> 0
A15: Jenter 10 | B15: =COUNTIFS(Sheet1!$R:$R,$A15,Sheet1!$S:$S,$A$1,Sheet1!$Q:$Q,B$3) -> 0 | C15: =COUNTIFS(Sheet1!$R:$R,$A15,Sheet1!$S:$S,$A$1,Sheet1!$Q:$Q,C$3) -> 0 | D15: =COUNTIFS(Sheet1!$R:$R,$A15,Sheet1!$S:$S,$A$1,Sheet1!$Q:$Q,D$3) -> 0 | E15: =COUNTIFS(Sheet1!$R:$R,$A15,Sheet1!$S:$S,$A$1,Sheet1!$Q:$Q,E$3) -> 0 | F15: =COUNTIFS(Sheet1!$R:$R,$A15,Sheet1!$S:$S,$A$1,Sheet1!$Q:$Q,F$3) -> 0 | G15: =COUNTIFS(Sheet1!$R:$R,$A15,Sheet1!$S:$S,$A$1,Sheet1!$Q:$Q,G$3) -> 0 | H15: =COUNTIFS(Sheet1!$R:$R,$A15,Sheet1!$S:$S,$A$1,Sheet1!$Q:$Q,H$3) -> 0 | I15: =COUNTIFS(Sheet1!$R:$R,$A15,Sheet1!$S:$S,$A$1,Sheet1!$Q:$Q,I$3) -> 0 | ... AA15: =COUNTIFS(Sheet1!$R:$R,$A15,Sheet1!$S:$S,$A$1,Sheet1!$Q:$Q,AA$3) -> 0
A16: Jenter 11 | B16: =COUNTIFS(Sheet1!$R:$R,$A16,Sheet1!$S:$S,$A$1,Sheet1!$Q:$Q,B$3) -> 0 | C16: =COUNTIFS(Sheet1!$R:$R,$A16,Sheet1!$S:$S,$A$1,Sheet1!$Q:$Q,C$3) -> 0 | D16: =COUNTIFS(Sheet1!$R:$R,$A16,Sheet1!$S:$S,$A$1,Sheet1!$Q:$Q,D$3) -> 0 | E16: =COUNTIFS(Sheet1!$R:$R,$A16,Sheet1!$S:$S,$A$1,Sheet1!$Q:$Q,E$3) -> 0 | F16: =COUNTIFS(Sheet1!$R:$R,$A16,Sheet1!$S:$S,$A$1,Sheet1!$Q:$Q,F$3) -> 0 | G16: =COUNTIFS(Sheet1!$R:$R,$A16,Sheet1!$S:$S,$A$1,Sheet1!$Q:$Q,G$3) -> 0 | H16: =COUNTIFS(Sheet1!$R:$R,$A16,Sheet1!$S:$S,$A$1,Sheet1!$Q:$Q,H$3) -> 0 | I16: =COUNTIFS(Sheet1!$R:$R,$A16,Sheet1!$S:$S,$A$1,Sheet1!$Q:$Q,I$3) -> 0 | ... AA16: =COUNTIFS(Sheet1!$R:$R,$A16,Sheet1!$S:$S,$A$1,Sheet1!$Q:$Q,AA$3) -> 0
A17: Jenter 12 | B17: =COUNTIFS(Sheet1!$R:$R,$A17,Sheet1!$S:$S,$A$1,Sheet1!$Q:$Q,B$3) -> 0 | C17: =COUNTIFS(Sheet1!$R:$R,$A17,Sheet1!$S:$S,$A$1,Sheet1!$Q:$Q,C$3) -> 0 | D17: =COUNTIFS(Sheet1!$R:$R,$A17,Sheet1!$S:$S,$A$1,Sheet1!$Q:$Q,D$3) -> 0 | E17: =COUNTIFS(Sheet1!$R:$R,$A17,Sheet1!$S:$S,$A$1,Sheet1!$Q:$Q,E$3) -> 0 | F17: =COUNTIFS(Sheet1!$R:$R,$A17,Sheet1!$S:$S,$A$1,Sheet1!$Q:$Q,F$3) -> 0 | G17: =COUNTIFS(Sheet1!$R:$R,$A17,Sheet1!$S:$S,$A$1,Sheet1!$Q:$Q,G$3) -> 0 | H17: =COUNTIFS(Sheet1!$R:$R,$A17,Sheet1!$S:$S,$A$1,Sheet1!$Q:$Q,H$3) -> 0 | I17: =COUNTIFS(Sheet1!$R:$R,$A17,Sheet1!$S:$S,$A$1,Sheet1!$Q:$Q,I$3) -> 0 | ... AA17: =COUNTIFS(Sheet1!$R:$R,$A17,Sheet1!$S:$S,$A$1,Sheet1!$Q:$Q,AA$3) -> 0
... A25: Menn senior | B25: =COUNTIFS(Sheet1!$R:$R,$A25,Sheet1!$S:$S,$A$1,Sheet1!$Q:$Q,B$3) -> 0 | C25: =COUNTIFS(Sheet1!$R:$R,$A25,Sheet1!$S:$S,$A$1,Sheet1!$Q:$Q,C$3) -> 0 | D25: =COUNTIFS(Sheet1!$R:$R,$A25,Sheet1!$S:$S,$A$1,Sheet1!$Q:$Q,D$3) -> 0 | E25: =COUNTIFS(Sheet1!$R:$R,$A25,Sheet1!$S:$S,$A$1,Sheet1!$Q:$Q,E$3) -> 0 | F25: =COUNTIFS(Sheet1!$R:$R,$A25,Sheet1!$S:$S,$A$1,Sheet1!$Q:$Q,F$3) -> 0 | G25: =COUNTIFS(Sheet1!$R:$R,$A25,Sheet1!$S:$S,$A$1,Sheet1!$Q:$Q,G$3) -> 0 | H25: =COUNTIFS(Sheet1!$R:$R,$A25,Sheet1!$S:$S,$A$1,Sheet1!$Q:$Q,H$3) -> 0 | I25: =COUNTIFS(Sheet1!$R:$R,$A25,Sheet1!$S:$S,$A$1,Sheet1!$Q:$Q,I$3) -> 0 | ... AA25: =COUNTIFS(Sheet1!$R:$R,$A25,Sheet1!$S:$S,$A$1,Sheet1!$Q:$Q,AA$3) -> 0
A27: SUM | B27: =SUM(B4:B26) -> 0 | C27: =SUM(C4:C26) -> 0 | D27: =SUM(D4:D26) -> 0 | E27: =SUM(E4:E26) -> 0 | F27: =SUM(F4:F26) -> 0 | G27: =SUM(G4:G26) -> 0 | H27: =SUM(H4:H26) -> 0 | I27: =SUM(I4:I26) -> 0 | ... AA27: =SUM(AA4:AA26) -> 0 | AB27: =SUM(B27:AA27) -> 87

Sheet Sheet3
A1: Tidsplan
A2: Seriestevne-2- Tromsøhallen - Mandag 24.02.2025 | S2: Antall utøvere i de ulike klasser og øvelser | AU2: Oppdatert: | AV2: 45626.618
A3: Ver 1.1 | B3: LØP | G3: HOPP | K3: KAST
B4: 60m | C4: 60m | D4: 300m | E4: 600m | F4: 1500m | G4: Lengde | H4: Tresteg | I4: Høyde | J4: Stav | K4: L.Ball | L4: Kule | M4: Kule | N4: Slegge | O4: Diskos | P4: Spyd | T4: 60mhk | U4: 80mhk | V4: 100mhk | W4: 110mhk | X4: 200mhk | Y4: 300mhk | Z4: 400mhk | AA4: 60m | AB4: 100m | AC4: 200m | AD4: 300m | AE4: 400m | AF4: 600m | AG4: 800m | AH4: 1500m | AI4: 3000m | AJ4: 5000m | AK4: Lengde | AL4: Tresteg | AM4: Høyde | AN4: Stav | AO4: L.Ball | AP4: Kule | AQ4: Slegge | AR4: Diskos | AS4: Spyd | AU4: Merknader
B5: Hekk | H5: Sør | K5: Sør | L5: 1 | M5: 2 | N5: Nord | O5: Nord | P5: Nord | S5: =SUM(T5:AS5) -> 87 | T5: =SUM(T6:T26) -> 0 | U5: =SUM(U6:U26) -> 0 | V5: =SUM(V6:V26) -> 0 | W5: =SUM(W6:W26) -> 0 | X5: =SUM(X6:X26) -> 0 | Y5: =SUM(Y6:Y26) -> 0 | Z5: =SUM(Z6:Z26) -> 0 | AA5: =SUM(AA6:AA26) -> 0 | ... AS5: =SUM(AS6:AS26) -> 0 | AU5: Antall starter | BH5: Fargekoder
A6: 0.69791667 | Q6: =A6 -> 0.69791667 | S6: FIFA
A7: 0.70138889 | Q7: =A7 -> 0.70138889 | S7: G-Rekrutt | T7: =Sheet2!B6 -> 0 | U7: =Sheet2!C6 -> 0 | V7: =Sheet2!D6 -> 0 | W7: =Sheet2!E6 -> 0 | X7: =Sheet2!F6 -> 0 | Y7: =Sheet2!G6 -> 0 | Z7: =Sheet2!H6 -> 0 | AA7: =Sheet2!I6 -> 0 | ... AC7: =Sheet2!K6 -> 0 | AD7: =IF(Sheet2!L6=0,"",Sheet2!L6) -> 8 | AE7: =IF(Sheet2!M6=0,"",Sheet2!M6) | AF7: =IF(Sheet2!N6=0,"",Sheet2!N6) | AG7: =IF(Sheet2!O6=0,"",Sheet2!O6) | AH7: =IF(Sheet2!P6=0,"",Sheet2!P6) | AI7: =IF(Sheet2!Q6=0,"",Sheet2!Q6) | AJ7: =IF(Sheet2!R6=0,"",Sheet2!R6) | AK7: =IF(Sheet2!S6=0,"",Sheet2!S6) | ... AP7: =IF(Sheet2!X6=0,"",Sheet2!X6) -> 8 | AQ7: =Sheet2!Y6 -> 0 | AR7: =Sheet2!Z6 -> 0 | AS7: =Sheet2!AA6 -> 0 | BH7: G-rekrutt
A8: 0.70486111 | Q8: =A8 -> 0.70486111 | S8: G-11 | T8: =Sheet2!B7 -> 0 | U8: =Sheet2!C7 -> 0 | V8: =Sheet2!D7 -> 0 | W8: =Sheet2!E7 -> 0 | X8: =Sheet2!F7 -> 0 | Y8: =Sheet2!G7 -> 0 | Z8: =Sheet2!H7 -> 0 | AA8: =Sheet2!I7 -> 0 | ... AC8: =Sheet2!K7 -> 0 | AD8: =IF(Sheet2!L7=0,"",Sheet2!L7) | AE8: =IF(Sheet2!M7=0,"",Sheet2!M7) | AF8: =IF(Sheet2!N7=0,"",Sheet2!N7) -> 1 | AG8: =IF(Sheet2!O7=0,"",Sheet2!O7) | AH8: =IF(Sheet2!P7=0,"",Sheet2!P7) | AI8: =IF(Sheet2!Q7=0,"",Sheet2!Q7) | AJ8: =IF(Sheet2!R7=0,"",Sheet2!R7) | AK8: =IF(Sheet2!S7=0,"",Sheet2!S7) | ... AP8: =IF(Sheet2!X7=0,"",Sheet2!X7) | AQ8: =Sheet2!Y7 -> 0 | AR8: =Sheet2!Z7 -> 0 | AS8: =Sheet2!AA7 -> 0
A9: 0.70833333 | D9: G-rekrutt 8 | G9: J13 2 | I9: G11 / G12 | L9: J11 / J12 | Q9: =A9 -> 0.70833333 | S9: G-12 | T9: =Sheet2!B8 -> 0 | U9: =Sheet2!C8 -> 0 | V9: =Sheet2!D8 -> 0 | W9: =Sheet2!E8 -> 0 | X9: =Sheet2!F8 -> 0 | Y9: =Sheet2!G8 -> 0 | Z9: =Sheet2!H8 -> 0 | AA9: =Sheet2!I8 -> 0 | ... AC9: =Sheet2!K8 -> 0 | AD9: =IF(Sheet2!L8=0,"",Sheet2!L8) | AE9: =IF(Sheet2!M8=0,"",Sheet2!M8) | AF9: =IF(Sheet2!N8=0,"",Sheet2!N8) -> 1 | AG9: =IF(Sheet2!O8=0,"",Sheet2!O8) | AH9: =IF(Sheet2!P8=0,"",Sheet2!P8) | AI9: =IF(Sheet2!Q8=0,"",Sheet2!Q8) | AJ9: =IF(Sheet2!R8=0,"",Sheet2!R8) | AK9: =IF(Sheet2!S8=0,"",Sheet2!S8) | ... AP9: =IF(Sheet2!X8=0,"",Sheet2!X8) | AQ9: =Sheet2!Y8 -> 0 | AR9: =Sheet2!Z8 -> 0 | AS9: =Sheet2!AA8 -> 0 | BH9: (3 forsøk)
A10: 0.71180556 | D10: J-rekrutt 4 | G10: (4 forsøk) | I10: 1+1 | L10: 5 + 1 | Q10: =A10 -> 0.71180556 | S10: G-13 | T10: =Sheet2!B9 -> 0 | U10: =Sheet2!C9 -> 0 | V10: =Sheet2!D9 -> 0 | W10: =Sheet2!E9 -> 0 | X10: =Sheet2!F9 -> 0 | Y10: =Sheet2!G9 -> 0 | Z10: =Sheet2!H9 -> 0 | AA10: =Sheet2!I9 -> 0 | ... AC10: =Sheet2!K9 -> 0 | AD10: =IF(Sheet2!L9=0,"",Sheet2!L9) | AE10: =IF(Sheet2!M9=0,"",Sheet2!M9) | AF10: =IF(Sheet2!N9=0,"",Sheet2!N9) | AG10: =IF(Sheet2!O9=0,"",Sheet2!O9) | AH10: =IF(Sheet2!P9=0,"",Sheet2!P9) | AI10: =IF(Sheet2!Q9=0,"",Sheet2!Q9) | AJ10: =IF(Sheet2!R9=0,"",Sheet2!R9) | AK10: =IF(Sheet2!S9=0,"",Sheet2!S9) | ... AP10: =IF(Sheet2!X9=0,"",Sheet2!X9) | AQ10: =Sheet2!Y9 -> 0 | AR10: =Sheet2!Z9 -> 0 | AS10: =Sheet2!AA9 -> 0
A11: 0.71527778 | E11: G16 | G11: G14 / J14 | L11: (4 forsøk) | Q11: =A11 -> 0.71527778 | S11: G-14 | T11: =Sheet2!B10 -> 0 | U11: =Sheet2!C10 -> 0 | V11: =Sheet2!D10 -> 0 | W11: =Sheet2!E10 -> 0 | X11: =Sheet2!F10 -> 0 | Y11: =Sheet2!G10 -> 0 | Z11: =Sheet2!H10 -> 0 | AA11: =Sheet2!I10 -> 0 | ... AC11: =Sheet2!K10 -> 0 | AD11: =IF(Sheet2!L10=0,"",Sheet2!L10) | AE11: =IF(Sheet2!M10=0,"",Sheet2!M10) | AF11: =IF(Sheet2!N10=0,"",Sheet2!N10) -> 2 | AG11: =IF(Sheet2!O10=0,"",Sheet2!O10) | AH11: =IF(Sheet2!P10=0,"",Sheet2!P10) | AI11: =IF(Sheet2!Q10=0,"",Sheet2!Q10) | AJ11: =IF(Sheet2!R10=0,"",Sheet2!R10) | AK11: =IF(Sheet2!S10=0,"",Sheet2!S10) -> 1 | ... AP11: =IF(Sheet2!X10=0,"",Sheet2!X10) -> 1 | AQ11: =Sheet2!Y10 -> 0 | AR11: =Sheet2!Z10 -> 0 | AS11: =Sheet2!AA10 -> 0 | BH11: J-rekrutt
A12: 0.71875 | E12: 3 | G12: 1 + 2 | I12: G-rekrutt | Q12: =A12 -> 0.71875 | S12: G-15 | T12: =Sheet2!B11 -> 0 | U12: =Sheet2!C11 -> 0 | V12: =Sheet2!D11 -> 0 | W12: =Sheet2!E11 -> 0 | X12: =Sheet2!F11 -> 0 | Y12: =Sheet2!G11 -> 0 | Z12: =Sheet2!H11 -> 0 | AA12: =Sheet2!I11 -> 0 | ... AC12: =Sheet2!K11 -> 0 | AD12: =IF(Sheet2!L11=0,"",Sheet2!L11) | AE12: =IF(Sheet2!M11=0,"",Sheet2!M11) | AF12: =IF(Sheet2!N11=0,"",Sheet2!N11) | AG12: =IF(Sheet2!O11=0,"",Sheet2!O11) | AH12: =IF(Sheet2!P11=0,"",Sheet2!P11) | AI12: =IF(Sheet2!Q11=0,"",Sheet2!Q11) | AJ12: =IF(Sheet2!R11=0,"",Sheet2!R11) | AK12: =IF(Sheet2!S11=0,"",Sheet2!S11) -> 1 | ... AP12: =IF(Sheet2!X11=0,"",Sheet2!X11) | AQ12: =Sheet2!Y11 -> 0 | AR12: =Sheet2!Z11 -> 0 | AS12: =Sheet2!AA11 -> 0
A13: 0.72222222 | E13: J16 | G13: (4 forsøk) | I13: 9 | Q13: =A13 -> 0.72222222 | S13: G-16 | T13: =Sheet2!B12 -> 0 | U13: =Sheet2!C12 -> 0 | V13: =Sheet2!D12 -> 0 | W13: =Sheet2!E12 -> 0 | X13: =Sheet2!F12 -> 0 | Y13: =Sheet2!G12 -> 0 | Z13: =Sheet2!H12 -> 0 | AA13: =Sheet2!I12 -> 0 | ... AC13: =Sheet2!K12 -> 0 | AD13: =IF(Sheet2!L12=0,"",Sheet2!L12) | AE13: =IF(Sheet2!M12=0,"",Sheet2!M12) | AF13: =IF(Sheet2!N12=0,"",Sheet2!N12) -> 3 | AG13: =IF(Sheet2!O12=0,"",Sheet2!O12) | AH13: =IF(Sheet2!P12=0,"",Sheet2!P12) | AI13: =IF(Sheet2!Q12=0,"",Sheet2!Q12) | AJ13: =IF(Sheet2!R12=0,"",Sheet2!R12) | AK13: =IF(Sheet2!S12=0,"",Sheet2!S12) -> 3 | ... AP13: =IF(Sheet2!X12=0,"",Sheet2!X12) -> 2 | AQ13: =Sheet2!Y12 -> 0 | AR13: =Sheet2!Z12 -> 0 | AS13: =Sheet2!AA12 -> 0 | BH13: (3 forsøk)
A14: 0.72569444 | E14: 1 | G14: G15 / G16 | L14: J-rekrutt | Q14: =A14 -> 0.72569444 | S14: G-17 | T14: =Sheet2!B13 -> 0 | U14: =Sheet2!C13 -> 0 | V14: =Sheet2!D13 -> 0 | W14: =Sheet2!E13 -> 0 | X14: =Sheet2!F13 -> 0 | Y14: =Sheet2!G13 -> 0 | Z14: =Sheet2!H13 -> 0 | AA14: =Sheet2!I13 -> 0 | ... AC14: =Sheet2!K13 -> 0 | AD14: =IF(Sheet2!L13=0,"",Sheet2!L13) | AE14: =IF(Sheet2!M13=0,"",Sheet2!M13) | AF14: =IF(Sheet2!N13=0,"",Sheet2!N13) | AG14: =IF(Sheet2!O13=0,"",Sheet2!O13) | AH14: =IF(Sheet2!P13=0,"",Sheet2!P13) | AI14: =IF(Sheet2!Q13=0,"",Sheet2!Q13) | AJ14: =IF(Sheet2!R13=0,"",Sheet2!R13) | AK14: =IF(Sheet2!S13=0,"",Sheet2!S13) | ... AP14: =IF(Sheet2!X13=0,"",Sheet2!X13) | AQ14: =Sheet2!Y13 -> 0 | AR14: =Sheet2!Z13 -> 0 | AS14: =Sheet2!AA13 -> 0
A15: 0.72916667 | E15: G11 / G12 | G15: J16 / J17 | L15: 4 | Q15: =A15 -> 0.72916667 | S15: G-18-19 | T15: =Sheet2!B14 -> 0 | U15: =Sheet2!C14 -> 0 | V15: =Sheet2!D14 -> 0 | W15: =Sheet2!E14 -> 0 | X15: =Sheet2!F14 -> 0 | Y15: =Sheet2!G14 -> 0 | Z15: =Sheet2!H14 -> 0 | AA15: =Sheet2!I14 -> 0 | ... AC15: =Sheet2!K14 -> 0 | AD15: =IF(Sheet2!L14=0,"",Sheet2!L14) | AE15: =IF(Sheet2!M14=0,"",Sheet2!M14) | AF15: =IF(Sheet2!N14=0,"",Sheet2!N14) | AG15: =IF(Sheet2!O14=0,"",Sheet2!O14) | AH15: =IF(Sheet2!P14=0,"",Sheet2!P14) | AI15: =IF(Sheet2!Q14=0,"",Sheet2!Q14) | AJ15: =IF(Sheet2!R14=0,"",Sheet2!R14) | AK15: =IF(Sheet2!S14=0,"",Sheet2!S14) | ... AP15: =IF(Sheet2!X14=0,"",Sheet2!X14) | AQ15: =Sheet2!Y14 -> 0 | AR15: =Sheet2!Z14 -> 0 | AS15: =Sheet2!AA14 -> 0 | BH15: G11 / G12
A16: 0.73263889 | E16: 1 + 1 | G16: 1 + 4 + 1 + 1 | L16: (3 forsøk) | Q16: =A16 -> 0.73263889 | S16: J-Rekrutt | T16: =Sheet2!B15 -> 0 | U16: =Sheet2!C15 -> 0 | V16: =Sheet2!D15 -> 0 | W16: =Sheet2!E15 -> 0 | X16: =Sheet2!F15 -> 0 | Y16: =Sheet2!G15 -> 0 | Z16: =Sheet2!H15 -> 0 | AA16: =Sheet2!I15 -> 0 | ... AC16: =Sheet2!K15 -> 0 | AD16: =IF(Sheet2!L15=0,"",Sheet2!L15) -> 4 | AE16: =IF(Sheet2!M15=0,"",Sheet2!M15) | AF16: =IF(Sheet2!N15=0,"",Sheet2!N15) | AG16: =IF(Sheet2!O15=0,"",Sheet2!O15) | AH16: =IF(Sheet2!P15=0,"",Sheet2!P15) | AI16: =IF(Sheet2!Q15=0,"",Sheet2!Q15) | AJ16: =IF(Sheet2!R15=0,"",Sheet2!R15) | AK16: =IF(Sheet2!S15=0,"",Sheet2!S15) | ... AP16: =IF(Sheet2!X15=0,"",Sheet2!X15) -> 4 | AQ16: =Sheet2!Y15 -> 0 | AR16: =Sheet2!Z15 -> 0 | AS16: =Sheet2!AA15 -> 0 | BH16: (3 forsøk)
A17: 0.73611111 | E17: J13 / J14 | G17: (6 forsøk) | Q17: =A17 -> 0.73611111 | S17: J-11 | T17: =Sheet2!B16 -> 0 | U17: =Sheet2!C16 -> 0 | V17: =Sheet2!D16 -> 0 | W17: =Sheet2!E16 -> 0 | X17: =Sheet2!F16 -> 0 | Y17: =Sheet2!G16 -> 0 | Z17: =Sheet2!H16 -> 0 | AA17: =Sheet2!I16 -> 0 | ... AC17: =Sheet2!K16 -> 0 | AD17: =IF(Sheet2!L16=0,"",Sheet2!L16) | AE17: =IF(Sheet2!M16=0,"",Sheet2!M16) | AF17: =IF(Sheet2!N16=0,"",Sheet2!N16) -> 5 | AG17: =IF(Sheet2!O16=0,"",Sheet2!O16) | AH17: =IF(Sheet2!P16=0,"",Sheet2!P16) | AI17: =IF(Sheet2!Q16=0,"",Sheet2!Q16) | AJ17: =IF(Sheet2!R16=0,"",Sheet2!R16) | AK17: =IF(Sheet2!S16=0,"",Sheet2!S16) | ... AP17: =IF(Sheet2!X16=0,"",Sheet2!X16) -> 5 | AQ17: =Sheet2!Y16 -> 0 | AR17: =Sheet2!Z16 -> 0 | AS17: =Sheet2!AA16 -> 0
A18: 0.73958333 | E18: 1 + 1 | Q18: =A18 -> 0.73958333 | S18: J-12 | T18: =Sheet2!B17 -> 0 | U18: =Sheet2!C17 -> 0 | V18: =Sheet2!D17 -> 0 | W18: =Sheet2!E17 -> 0 | X18: =Sheet2!F17 -> 0 | Y18: =Sheet2!G17 -> 0 | Z18: =Sheet2!H17 -> 0 | AA18: =Sheet2!I17 -> 0 | ... AC18: =Sheet2!K17 -> 0 | AD18: =IF(Sheet2!L17=0,"",Sheet2!L17) | AE18: =IF(Sheet2!M17=0,"",Sheet2!M17) | AF18: =IF(Sheet2!N17=0,"",Sheet2!N17) | AG18: =IF(Sheet2!O17=0,"",Sheet2!O17) | AH18: =IF(Sheet2!P17=0,"",Sheet2!P17) | AI18: =IF(Sheet2!Q17=0,"",Sheet2!Q17) | AJ18: =IF(Sheet2!R17=0,"",Sheet2!R17) | AK18: =IF(Sheet2!S17=0,"",Sheet2!S17) | ... AP18: =IF(Sheet2!X17=0,"",Sheet2!X17) -> 1 | AQ18: =Sheet2!Y17 -> 0 | AR18: =Sheet2!Z17 -> 0 | AS18: =Sheet2!AA17 -> 0 | BH18: G13 / G14
A19: 0.74305556 | E19: J11 | I19: J-rekrutt | Q19: =A19 -> 0.74305556 | S19: J-13 | T19: =Sheet2!B18 -> 0 | U19: =Sheet2!C18 -> 0 | V19: =Sheet2!D18 -> 0 | W19: =Sheet2!E18 -> 0 | X19: =Sheet2!F18 -> 0 | Y19: =Sheet2!G18 -> 0 | Z19: =Sheet2!H18 -> 0 | AA19: =Sheet2!I18 -> 0 | ... AC19: =Sheet2!K18 -> 0 | AD19: =IF(Sheet2!L18=0,"",Sheet2!L18) | AE19: =IF(Sheet2!M18=0,"",Sheet2!M18) | AF19: =IF(Sheet2!N18=0,"",Sheet2!N18) -> 1 | AG19: =IF(Sheet2!O18=0,"",Sheet2!O18) | AH19: =IF(Sheet2!P18=0,"",Sheet2!P18) -> 1 | AI19: =IF(Sheet2!Q18=0,"",Sheet2!Q18) | AJ19: =IF(Sheet2!R18=0,"",Sheet2!R18) | AK19: =IF(Sheet2!S18=0,"",Sheet2!S18) -> 2 | ... AP19: =IF(Sheet2!X18=0,"",Sheet2!X18) -> 3 | AQ19: =Sheet2!Y18 -> 0 | AR19: =Sheet2!Z18 -> 0 | AS19: =Sheet2!AA18 -> 0
A20: 0.74652778 | E20: 5 | I20: 4 | Q20: =A20 -> 0.74652778 | S20: J-14 | T20: =Sheet2!B19 -> 0 | U20: =Sheet2!C19 -> 0 | V20: =Sheet2!D19 -> 0 | W20: =Sheet2!E19 -> 0 | X20: =Sheet2!F19 -> 0 | Y20: =Sheet2!G19 -> 0 | Z20: =Sheet2!H19 -> 0 | AA20: =Sheet2!I19 -> 0 | ... AC20: =Sheet2!K19 -> 0 | AD20: =IF(Sheet2!L19=0,"",Sheet2!L19) | AE20: =IF(Sheet2!M19=0,"",Sheet2!M19) | AF20: =IF(Sheet2!N19=0,"",Sheet2!N19) -> 1 | AG20: =IF(Sheet2!O19=0,"",Sheet2!O19) | AH20: =IF(Sheet2!P19=0,"",Sheet2!P19) | AI20: =IF(Sheet2!Q19=0,"",Sheet2!Q19) | AJ20: =IF(Sheet2!R19=0,"",Sheet2!R19) | AK20: =IF(Sheet2!S19=0,"",Sheet2!S19) -> 2 | ... AP20: =IF(Sheet2!X19=0,"",Sheet2!X19) -> 2 | AQ20: =Sheet2!Y19 -> 0 | AR20: =Sheet2!Z19 -> 0 | AS20: =Sheet2!AA19 -> 0 | BH20: (3 forsøk)
A21: 0.75 | E21: G14 | Q21: =A21 -> 0.75 | S21: J-15 | T21: =Sheet2!B20 -> 0 | U21: =Sheet2!C20 -> 0 | V21: =Sheet2!D20 -> 0 | W21: =Sheet2!E20 -> 0 | X21: =Sheet2!F20 -> 0 | Y21: =Sheet2!G20 -> 0 | Z21: =Sheet2!H20 -> 0 | AA21: =Sheet2!I20 -> 0 | ... AC21: =Sheet2!K20 -> 0 | AD21: =IF(Sheet2!L20=0,"",Sheet2!L20) | AE21: =IF(Sheet2!M20=0,"",Sheet2!M20) | AF21: =IF(Sheet2!N20=0,"",Sheet2!N20) | AG21: =IF(Sheet2!O20=0,"",Sheet2!O20) | AH21: =IF(Sheet2!P20=0,"",Sheet2!P20) | AI21: =IF(Sheet2!Q20=0,"",Sheet2!Q20) | AJ21: =IF(Sheet2!R20=0,"",Sheet2!R20) | AK21: =IF(Sheet2!S20=0,"",Sheet2!S20) | ... AP21: =IF(Sheet2!X20=0,"",Sheet2!X20) | AQ21: =Sheet2!Y20 -> 0 | AR21: =Sheet2!Z20 -> 0 | AS21: =Sheet2!AA20 -> 0
A22: 0.75347222 | E22: 2 | I22: J11 + J12 | M22: G-rekrutt | Q22: =A22 -> 0.75347222 | S22: J-16 | T22: =Sheet2!B21 -> 0 | U22: =Sheet2!C21 -> 0 | V22: =Sheet2!D21 -> 0 | W22: =Sheet2!E21 -> 0 | X22: =Sheet2!F21 -> 0 | Y22: =Sheet2!G21 -> 0 | Z22: =Sheet2!H21 -> 0 | AA22: =Sheet2!I21 -> 0 | ... AC22: =Sheet2!K21 -> 0 | AD22: =IF(Sheet2!L21=0,"",Sheet2!L21) | AE22: =IF(Sheet2!M21=0,"",Sheet2!M21) | AF22: =IF(Sheet2!N21=0,"",Sheet2!N21) -> 1 | AG22: =IF(Sheet2!O21=0,"",Sheet2!O21) | AH22: =IF(Sheet2!P21=0,"",Sheet2!P21) | AI22: =IF(Sheet2!Q21=0,"",Sheet2!Q21) | AJ22: =IF(Sheet2!R21=0,"",Sheet2!R21) | AK22: =IF(Sheet2!S21=0,"",Sheet2!S21) -> 1 | ... AP22: =IF(Sheet2!X21=0,"",Sheet2!X21) | AQ22: =Sheet2!Y21 -> 0 | AR22: =Sheet2!Z21 -> 0 | AS22: =Sheet2!AA21 -> 0 | BH22: J11 / J12
A23: 0.75694444 | F23: J13 | I23: 5 + 1 | L23: G16 / J17 | M23: 8 | Q23: =A23 -> 0.75694444 | S23: J-17 | T23: =Sheet2!B22 -> 0 | U23: =Sheet2!C22 -> 0 | V23: =Sheet2!D22 -> 0 | W23: =Sheet2!E22 -> 0 | X23: =Sheet2!F22 -> 0 | Y23: =Sheet2!G22 -> 0 | Z23: =Sheet2!H22 -> 0 | AA23: =Sheet2!I22 -> 0 | ... AC23: =Sheet2!K22 -> 0 | AD23: =IF(Sheet2!L22=0,"",Sheet2!L22) | AE23: =IF(Sheet2!M22=0,"",Sheet2!M22) | AF23: =IF(Sheet2!N22=0,"",Sheet2!N22) | AG23: =IF(Sheet2!O22=0,"",Sheet2!O22) | AH23: =IF(Sheet2!P22=0,"",Sheet2!P22) | AI23: =IF(Sheet2!Q22=0,"",Sheet2!Q22) | AJ23: =IF(Sheet2!R22=0,"",Sheet2!R22) | AK23: =IF(Sheet2!S22=0,"",Sheet2!S22) -> 1 | ... AP23: =IF(Sheet2!X22=0,"",Sheet2!X22) -> 1 | AQ23: =Sheet2!Y22 -> 0 | AR23: =Sheet2!Z22 -> 0 | AS23: =Sheet2!AA22 -> 0
A24: 0.76041667 | F24: 1 | L24: 3 + 1 | M24: (3 forsøk) | Q24: =A24 -> 0.76041667 | S24: J-18-19 | T24: =Sheet2!B23 -> 0 | U24: =Sheet2!C23 -> 0 | V24: =Sheet2!D23 -> 0 | W24: =Sheet2!E23 -> 0 | X24: =Sheet2!F23 -> 0 | Y24: =Sheet2!G23 -> 0 | Z24: =Sheet2!H23 -> 0 | AA24: =Sheet2!I23 -> 0 | ... AC24: =Sheet2!K23 -> 0 | AD24: =IF(Sheet2!L23=0,"",Sheet2!L23) | AE24: =IF(Sheet2!M23=0,"",Sheet2!M23) | AF24: =IF(Sheet2!N23=0,"",Sheet2!N23) | AG24: =IF(Sheet2!O23=0,"",Sheet2!O23) | AH24: =IF(Sheet2!P23=0,"",Sheet2!P23) | AI24: =IF(Sheet2!Q23=0,"",Sheet2!Q23) | AJ24: =IF(Sheet2!R23=0,"",Sheet2!R23) | AK24: =IF(Sheet2!S23=0,"",Sheet2!S23) | ... AP24: =IF(Sheet2!X23=0,"",Sheet2!X23) | AQ24: =Sheet2!Y23 -> 0 | AR24: =Sheet2!Z23 -> 0 | AS24: =Sheet2!AA23 -> 0 | BH24: (3forsøk)
A25: 0.76388889 | E25: FIFA (Stafett) | L25: (6 forsøk) | Q25: =A25 -> 0.76388889 | S25: KS | T25: =Sheet2!B24 -> 0 | U25: =Sheet2!C24 -> 0 | V25: =Sheet2!D24 -> 0 | W25: =Sheet2!E24 -> 0 | X25: =Sheet2!F24 -> 0 | Y25: =Sheet2!G24 -> 0 | Z25: =Sheet2!H24 -> 0 | AA25: =Sheet2!I24 -> 0 | ... AC25: =Sheet2!K24 -> 0 | AD25: =IF(Sheet2!L24=0,"",Sheet2!L24) | AE25: =IF(Sheet2!M24=0,"",Sheet2!M24) | AF25: =IF(Sheet2!N24=0,"",Sheet2!N24) | AG25: =IF(Sheet2!O24=0,"",Sheet2!O24) | AH25: =IF(Sheet2!P24=0,"",Sheet2!P24) | AI25: =IF(Sheet2!Q24=0,"",Sheet2!Q24) | AJ25: =IF(Sheet2!R24=0,"",Sheet2!R24) | AK25: =IF(Sheet2!S24=0,"",Sheet2!S24) | ... AP25: =IF(Sheet2!X24=0,"",Sheet2!X24) | AQ25: =Sheet2!Y24 -> 0 | AR25: =Sheet2!Z24 -> 0 | AS25: =Sheet2!AA24 -> 0
A26: 0.76736111 | Q26: =A26 -> 0.76736111 | S26: MS | T26: =Sheet2!B25 -> 0 | U26: =Sheet2!C25 -> 0 | V26: =Sheet2!D25 -> 0 | W26: =Sheet2!E25 -> 0 | X26: =Sheet2!F25 -> 0 | Y26: =Sheet2!G25 -> 0 | Z26: =Sheet2!H25 -> 0 | AA26: =Sheet2!I25 -> 0 | ... AC26: =Sheet2!K25 -> 0 | AD26: =IF(Sheet2!L25=0,"",Sheet2!L25) | AE26: =IF(Sheet2!M25=0,"",Sheet2!M25) | AF26: =IF(Sheet2!N25=0,"",Sheet2!N25) | AG26: =IF(Sheet2!O25=0,"",Sheet2!O25) | AH26: =IF(Sheet2!P25=0,"",Sheet2!P25) | AI26: =IF(Sheet2!Q25=0,"",Sheet2!Q25) | AJ26: =IF(Sheet2!R25=0,"",Sheet2!R25) | AK26: =IF(Sheet2!S25=0,"",Sheet2!S25) | ... AP26: =IF(Sheet2!X25=0,"",Sheet2!X25) | AQ26: =Sheet2!Y25 -> 0 | AR26: =Sheet2!Z25 -> 0 | AS26: =Sheet2!AA25 -> 0 | BH26: J13 / J14
A27: 0.77083333 | L27: G14 / J13 / J14 | Q27: =A27 -> 0.77083333
A28: 0.77430556 | L28: 1 + 3 + 2 | M28: FIFA | Q28: =A28 -> 0.77430556 | BH28: (3forsøk)
A29: 0.77777778 | L29: (4 forsøk) | Q29: =A29 -> 0.77777778 | S29: Tidsbruk | AU29: Hor Hopp | AW29: Høyde | AZ29: Stav | BD29: Kast
A30: 0.78125 | Q30: =A30 -> 0.78125 | S30: FIFA | AK30: =IF(SUM(AK6)=0,"",SUM(AK6)*$AU30*$AV30) | AL30: =SUM(AL6)*$AU30*$AV30 -> 0 | AM30: =IF(SUM(AM6)=0,"",(SUM(AM6)*$AW30*$AX30)+$AY30) | AN30: =IF(SUM(AN6)=0,"",(SUM(AN6)*$AZ30*$BA30)+$BB30) | AO30: =SUM(AO6)*$BD30*$BE30 -> 0 | AP30: =IF(SUM(AP6)=0,"",SUM(AP6)*$BD30*$BE30) | AQ30: =SUM(AQ6)*$BD30*$BE30 -> 0 | AR30: =SUM(AR6)*$BD30*$BE30 -> 0 | AS30: =SUM(AS6)*$BD30*$BE30 -> 0 | AU30: 1 | AV30: 3 | AW30: 0.75 | AX30: 8 | AY30: 5 | BD30: 1 | BE30: 3 | BH30: G15 +
A31: 0.78472222 | B31: Opprydding | Q31: =A31 -> 0.78472222 | S31: G-rekrutt | AK31: =IF(SUM(AK7)=0,"",SUM(AK7)*$AU31*$AV31) | AL31: =SUM(AL7)*$AU31*$AV31 -> 0 | AM31: =IF(SUM(AM7)=0,"",((SUM(AM7)*$AW31*$AX31)+$AY31)) -> 33.75 | AN31: =IF(SUM(AN7)=0,"",(SUM(AN7)*$AZ31*$BA31)+$BB31) | AO31: =SUM(AO7)*$BD31*$BE31 -> 0 | AP31: =IF(SUM(AP7)=0,"",SUM(AP7)*$BD31*$BE31) -> 24 | AQ31: =SUM(AQ7)*$BD31*$BE31 -> 0 | AR31: =SUM(AR7)*$BD31*$BE31 -> 0 | AS31: =SUM(AS7)*$BD31*$BE31 -> 0 | AU31: 1 | AV31: 3 | AW31: 0.75 | AX31: 5 | BD31: 1 | BE31: 3
A32: 0.78819444 | Q32: =A32 -> 0.78819444 | S32: G-11 | AK32: =IF(SUM(AK8)=0,"",SUM(AK8)*$AU32*$AV32) | AL32: =SUM(AL8)*$AU32*$AV32 -> 0 | AM32: =IF(SUM(AM8)=0,"",((SUM(AM8)*$AW32*$AX32)+$AY32)) -> 11 | AN32: =IF(SUM(AN8)=0,"",(SUM(AN8)*$AZ32*$BA32)+$BB32) | AO32: =SUM(AO8)*$BD32*$BE32 -> 0 | AP32: =IF(SUM(AP8)=0,"",SUM(AP8)*$BD32*$BE32) | AQ32: =SUM(AQ8)*$BD32*$BE32 -> 0 | AR32: =SUM(AR8)*$BD32*$BE32 -> 0 | AS32: =SUM(AS8)*$BD32*$BE32 -> 0 | AU32: 1 | AV32: 4 | AW32: 0.75 | AX32: 8 | AY32: 5 | AZ32: 1.25 | BA32: 8 | BB32: 5 | BD32: 1 | BE32: 4 | BH32: (6 forsøk)
A33: 0.79166667 | B33: UTE AV HALLEN | Q33: =A33 -> 0.79166667 | S33: G-12 | AK33: =IF(SUM(AK9)=0,"",SUM(AK9)*$AU33*$AV33) | AL33: =SUM(AL9)*$AU33*$AV33 -> 0 | AM33: =IF(SUM(AM9)=0,"",((SUM(AM9)*$AW33*$AX33)+$AY33)) -> 11 | AN33: =IF(SUM(AN9)=0,"",(SUM(AN9)*$AZ33*$BA33)+$BB33) | AO33: =SUM(AO9)*$BD33*$BE33 -> 0 | AP33: =IF(SUM(AP9)=0,"",SUM(AP9)*$BD33*$BE33) | AQ33: =SUM(AQ9)*$BD33*$BE33 -> 0 | AR33: =SUM(AR9)*$BD33*$BE33 -> 0 | AS33: =SUM(AS9)*$BD33*$BE33 -> 0 | AU33: 1 | AV33: 4 | AW33: 0.75 | AX33: 8 | AY33: 5 | AZ33: 1.25 | BA33: 8 | BB33: 5 | BD33: 1 | BE33: 4
S34: G-13 | AK34: =IF(SUM(AK10)=0,"",SUM(AK10)*$AU34*$AV34) | AL34: =SUM(AL10)*$AU34*$AV34 -> 0 | AM34: =IF(SUM(AM10)=0,"",((SUM(AM10)*$AW34*$AX34)+$AY34)) | AN34: =IF(SUM(AN10)=0,"",(SUM(AN10)*$AZ34*$BA34)+$BB34) | AO34: =SUM(AO10)*$BD34*$BE34 -> 0 | AP34: =IF(SUM(AP10)=0,"",SUM(AP10)*$BD34*$BE34) | AQ34: =SUM(AQ10)*$BD34*$BE34 -> 0 | AR34: =SUM(AR10)*$BD34*$BE34 -> 0 | AS34: =SUM(AS10)*$BD34*$BE34 -> 0 | AU34: 1 | AV34: 4 | AW34: 0.75 | AX34: 8 | AY34: 5 | AZ34: 1.25 | BA34: 8 | BB34: 5 | BD34: 1 | BE34: 4 | BH34: J15 + | BJ34: Arrangørhåndbok
I35: Dommer/funksjonærteam | S35: G-14 | AK35: =IF(SUM(AK11)=0,"",SUM(AK11)*$AU35*$AV35) -> 6 | AL35: =SUM(AL11)*$AU35*$AV35 -> 0 | AM35: =IF(SUM(AM11)=0,"",((SUM(AM11)*$AW35*$AX35)+$AY35)) | AN35: =IF(SUM(AN11)=0,"",(SUM(AN11)*$AZ35*$BA35)+$BB35) | AO35: =SUM(AO11)*$BD35*$BE35 -> 0 | AP35: =IF(SUM(AP11)=0,"",SUM(AP11)*$BD35*$BE35) -> 4 | AQ35: =SUM(AQ11)*$BD35*$BE35 -> 0 | AR35: =SUM(AR11)*$BD35*$BE35 -> 0 | AS35: =SUM(AS11)*$BD35*$BE35 -> 0 | AU35: 1 | AV35: 6 | AW35: 0.75 | AX35: 8 | AY35: 5 | AZ35: 1.25 | BA35: 8 | BB35: 5 | BD35: 1 | BE35: 4 | BL35: Tid/forsøk | BM35: Forsøk
I36: Team 1 | L36: Løp | S36: G-15 | AK36: =IF(SUM(AK12)=0,"",SUM(AK12)*$AU36*$AV36) -> 6 | AL36: =SUM(AL12)*$AU36*$AV36 -> 0 | AM36: =IF(SUM(AM12)=0,"",((SUM(AM12)*$AW36*$AX36)+$AY36)) | AN36: =IF(SUM(AN12)=0,"",(SUM(AN12)*$AZ36*$BA36)+$BB36) | AO36: =SUM(AO12)*$BD36*$BE36 -> 0 | AP36: =IF(SUM(AP12)=0,"",SUM(AP12)*$BD36*$BE36) | AQ36: =SUM(AQ12)*$BD36*$BE36 -> 0 | AR36: =SUM(AR12)*$BD36*$BE36 -> 0 | AS36: =SUM(AS12)*$BD36*$BE36 -> 0 | AU36: 1 | AV36: 6 | AW36: 0.75 | AX36: 8 | AY36: 5 | AZ36: 1.25 | BA36: 8 | BB36: 5 | BD36: 1 | BE36: 6 | BH36: (6 forsøk) | BJ36: Kast: | BL36: 1 | BM36: 3
I37: Team 2 | L37: Lengde/Kule rekrutt | S37: G-16 | AK37: =IF(SUM(AK13)=0,"",SUM(AK13)*$AU37*$AV37) -> 18 | AL37: =SUM(AL13)*$AU37*$AV37 -> 0 | AM37: =IF(SUM(AM13)=0,"",((SUM(AM13)*$AW37*$AX37)+$AY37)) | AN37: =IF(SUM(AN13)=0,"",(SUM(AN13)*$AZ37*$BA37)+$BB37) | AO37: =SUM(AO13)*$BD37*$BE37 -> 0 | AP37: =IF(SUM(AP13)=0,"",SUM(AP13)*$BD37*$BE37) -> 12 | AQ37: =SUM(AQ13)*$BD37*$BE37 -> 0 | AR37: =SUM(AR13)*$BD37*$BE37 -> 0 | AS37: =SUM(AS13)*$BD37*$BE37 -> 0 | AU37: 1 | AV37: 6 | AW37: 0.75 | AX37: 8 | AY37: 5 | AZ37: 1.25 | BA37: 8 | BB37: 5 | BD37: 1 | BE37: 6 | BJ37: Lengde/tresteg: | BL37: 1 | BM37: 3
I38: Team 3 | L38: Høyde | S38: G-17 | AK38: =IF(SUM(AK14)=0,"",SUM(AK14)*$AU38*$AV38) | AL38: =SUM(AL14)*$AU38*$AV38 -> 0 | AM38: =IF(SUM(AM14)=0,"",((SUM(AM14)*$AW38*$AX38)+$AY38)) | AN38: =IF(SUM(AN14)=0,"",(SUM(AN14)*$AZ38*$BA38)+$BB38) | AO38: =SUM(AO14)*$BD38*$BE38 -> 0 | AP38: =IF(SUM(AP14)=0,"",SUM(AP14)*$BD38*$BE38) | AQ38: =SUM(AQ14)*$BD38*$BE38 -> 0 | AR38: =SUM(AR14)*$BD38*$BE38 -> 0 | AS38: =SUM(AS14)*$BD38*$BE38 -> 0 | AU38: 1 | AV38: 6 | AW38: 0.75 | AX38: 8 | AY38: 5 | AZ38: 1.25 | BA38: 8 | BB38: 5 | BD38: 1 | BE38: 6 | BH38: G11 / G12 /G13 / G14 | BJ38: Høyde: | BL38: 1 | BM38: 8
I39: Team 4 | L39: Kule 1 | S39: G-18/19 | AK39: =IF(SUM(AK15)=0,"",SUM(AK15)*$AU39*$AV39) | AL39: =SUM(AL15)*$AU39*$AV39 -> 0 | AM39: =IF(SUM(AM15)=0,"",((SUM(AM15)*$AW39*$AX39)+$AY39)) | AN39: =IF(SUM(AN15)=0,"",(SUM(AN15)*$AZ39*$BA39)+$BB39) | AO39: =SUM(AO15)*$BD39*$BE39 -> 0 | AP39: =IF(SUM(AP15)=0,"",SUM(AP15)*$BD39*$BE39) | AQ39: =SUM(AQ15)*$BD39*$BE39 -> 0 | AR39: =SUM(AR15)*$BD39*$BE39 -> 0 | AS39: =SUM(AS15)*$BD39*$BE39 -> 0 | AU39: 1 | AV39: 6 | AW39: 0.75 | AX39: 8 | AY39: 5 | AZ39: 1.25 | BA39: 8 | BB39: 5 | BD39: 1 | BE39: 6 | BJ39: Stav: | BL39: 1.5 | BM39: 8
S40: J-rekrutt | AK40: =IF(SUM(AK16)=0,"",SUM(AK16)*$AU40*$AV40) | AL40: =SUM(AL16)*$AU40*$AV40 -> 0 | AM40: =IF(SUM(AM16)=0,"",((SUM(AM16)*$AW40*$AX40)+$AY40)) -> 15 | AN40: =IF(SUM(AN16)=0,"",(SUM(AN16)*$AZ40*$BA40)+$BB40) | AO40: =SUM(AO16)*$BD40*$BE40 -> 0 | AP40: =IF(SUM(AP16)=0,"",SUM(AP16)*$BD40*$BE40) -> 12 | AQ40: =SUM(AQ16)*$BD40*$BE40 -> 0 | AR40: =SUM(AR16)*$BD40*$BE40 -> 0 | AS40: =SUM(AS16)*$BD40*$BE40 -> 0 | AU40: 1 | AV40: 3 | AW40: 0.75 | AX40: 5 | BD40: 1 | BE40: 3
...
